2024-06-24 19:10:53,557 -  nornir.core -     INFO -        run() - Running task 'netconf_edit_config' with args {'config': '<config>\n    <interfaces xmlns="urn:ietf:params:xml:ns:yang:ietf-interfaces">\n        <interface>\n            <name>Ethernet1</name>\n            <description>scrapli was here!</description>\n        </interface>\n    </interfaces>\n</config>'} on 1 hosts
2024-06-24 19:10:53,608 - nornir.core.task -    ERROR -      start() - Host 'R2': task 'netconf_edit_config' failed with traceback:
Traceback (most recent call last):
  File "/home/admin/.local/share/virtualenvs/Dev-jffJP19G/lib/python3.9/site-packages/nornir/core/task.py", line 99, in start
    r = self.task(self, **self.params)
  File "/home/admin/.local/share/virtualenvs/Dev-jffJP19G/lib/python3.9/site-packages/nornir_scrapli/tasks/netconf/edit_config.py", line 38, in netconf_edit_config
    scrapli_conn = task.host.get_connection("scrapli_netconf", task.nornir.config)
  File "/home/admin/.local/share/virtualenvs/Dev-jffJP19G/lib/python3.9/site-packages/nornir/core/inventory.py", line 494, in get_connection
    self.open_connection(
  File "/home/admin/.local/share/virtualenvs/Dev-jffJP19G/lib/python3.9/site-packages/nornir/core/inventory.py", line 546, in open_connection
    conn_obj.open(
  File "/home/admin/.local/share/virtualenvs/Dev-jffJP19G/lib/python3.9/site-packages/nornir_scrapli/connection.py", line 287, in open
    connection.open()
  File "/home/admin/.local/share/virtualenvs/Dev-jffJP19G/lib/python3.9/site-packages/scrapli_netconf/driver/sync_driver.py", line 117, in open
    self.channel.channel_authenticate_netconf(
  File "/home/admin/.local/share/virtualenvs/Dev-jffJP19G/lib/python3.9/site-packages/scrapli/decorators.py", line 223, in decorate
    return _multiprocessing_timeout(
  File "/home/admin/.local/share/virtualenvs/Dev-jffJP19G/lib/python3.9/site-packages/scrapli/decorators.py", line 114, in _multiprocessing_timeout
    return future.result()
  File "/usr/lib64/python3.9/concurrent/futures/_base.py", line 439, in result
    return self.__get_result()
  File "/usr/lib64/python3.9/concurrent/futures/_base.py", line 391, in __get_result
    raise self._exception
  File "/usr/lib64/python3.9/concurrent/futures/thread.py", line 58, in run
    result = self.fn(*self.args, **self.kwargs)
  File "/home/admin/.local/share/virtualenvs/Dev-jffJP19G/lib/python3.9/site-packages/scrapli_netconf/channel/sync_channel.py", line 107, in channel_authenticate_netconf
    self._ssh_message_handler(output=authenticate_buf)
  File "/home/admin/.local/share/virtualenvs/Dev-jffJP19G/lib/python3.9/site-packages/scrapli/channel/base_channel.py", line 476, in _ssh_message_handler
    raise ScrapliAuthenticationFailed(msg)
scrapli.exceptions.ScrapliAuthenticationFailed: Could not resolve address for host

2024-06-24 19:11:39,837 -  nornir.core -     INFO -        run() - Running task 'netconf_edit_config' with args {'config': '<config>\n    <interfaces xmlns="urn:ietf:params:xml:ns:yang:ietf-interfaces">\n        <interface>\n            <name>Ethernet1</name>\n            <description>scrapli was here!</description>\n        </interface>\n    </interfaces>\n</config>'} on 1 hosts
2024-06-24 19:11:39,875 - nornir.core.task -    ERROR -      start() - Host 'R2': task 'netconf_edit_config' failed with traceback:
Traceback (most recent call last):
  File "/home/admin/.local/share/virtualenvs/Dev-jffJP19G/lib/python3.9/site-packages/nornir/core/task.py", line 99, in start
    r = self.task(self, **self.params)
  File "/home/admin/.local/share/virtualenvs/Dev-jffJP19G/lib/python3.9/site-packages/nornir_scrapli/tasks/netconf/edit_config.py", line 38, in netconf_edit_config
    scrapli_conn = task.host.get_connection("scrapli_netconf", task.nornir.config)
  File "/home/admin/.local/share/virtualenvs/Dev-jffJP19G/lib/python3.9/site-packages/nornir/core/inventory.py", line 494, in get_connection
    self.open_connection(
  File "/home/admin/.local/share/virtualenvs/Dev-jffJP19G/lib/python3.9/site-packages/nornir/core/inventory.py", line 546, in open_connection
    conn_obj.open(
  File "/home/admin/.local/share/virtualenvs/Dev-jffJP19G/lib/python3.9/site-packages/nornir_scrapli/connection.py", line 287, in open
    connection.open()
  File "/home/admin/.local/share/virtualenvs/Dev-jffJP19G/lib/python3.9/site-packages/scrapli_netconf/driver/sync_driver.py", line 117, in open
    self.channel.channel_authenticate_netconf(
  File "/home/admin/.local/share/virtualenvs/Dev-jffJP19G/lib/python3.9/site-packages/scrapli/decorators.py", line 223, in decorate
    return _multiprocessing_timeout(
  File "/home/admin/.local/share/virtualenvs/Dev-jffJP19G/lib/python3.9/site-packages/scrapli/decorators.py", line 114, in _multiprocessing_timeout
    return future.result()
  File "/usr/lib64/python3.9/concurrent/futures/_base.py", line 439, in result
    return self.__get_result()
  File "/usr/lib64/python3.9/concurrent/futures/_base.py", line 391, in __get_result
    raise self._exception
  File "/usr/lib64/python3.9/concurrent/futures/thread.py", line 58, in run
    result = self.fn(*self.args, **self.kwargs)
  File "/home/admin/.local/share/virtualenvs/Dev-jffJP19G/lib/python3.9/site-packages/scrapli_netconf/channel/sync_channel.py", line 107, in channel_authenticate_netconf
    self._ssh_message_handler(output=authenticate_buf)
  File "/home/admin/.local/share/virtualenvs/Dev-jffJP19G/lib/python3.9/site-packages/scrapli/channel/base_channel.py", line 476, in _ssh_message_handler
    raise ScrapliAuthenticationFailed(msg)
scrapli.exceptions.ScrapliAuthenticationFailed: Could not resolve address for host

2024-06-24 19:15:12,947 -  nornir.core -     INFO -        run() - Running task 'netconf_edit_config' with args {'config': '<config>\n    <interfaces xmlns="urn:ietf:params:xml:ns:yang:ietf-interfaces">\n        <interface>\n            <name>Ethernet1</name>\n            <description>scrapli was here!</description>\n        </interface>\n    </interfaces>\n</config>'} on 1 hosts
2024-06-24 19:15:12,981 - nornir.core.task -    ERROR -      start() - Host 'R2': task 'netconf_edit_config' failed with traceback:
Traceback (most recent call last):
  File "/home/admin/.local/share/virtualenvs/Dev-jffJP19G/lib/python3.9/site-packages/nornir/core/task.py", line 99, in start
    r = self.task(self, **self.params)
  File "/home/admin/.local/share/virtualenvs/Dev-jffJP19G/lib/python3.9/site-packages/nornir_scrapli/tasks/netconf/edit_config.py", line 38, in netconf_edit_config
    scrapli_conn = task.host.get_connection("scrapli_netconf", task.nornir.config)
  File "/home/admin/.local/share/virtualenvs/Dev-jffJP19G/lib/python3.9/site-packages/nornir/core/inventory.py", line 494, in get_connection
    self.open_connection(
  File "/home/admin/.local/share/virtualenvs/Dev-jffJP19G/lib/python3.9/site-packages/nornir/core/inventory.py", line 546, in open_connection
    conn_obj.open(
  File "/home/admin/.local/share/virtualenvs/Dev-jffJP19G/lib/python3.9/site-packages/nornir_scrapli/connection.py", line 287, in open
    connection.open()
  File "/home/admin/.local/share/virtualenvs/Dev-jffJP19G/lib/python3.9/site-packages/scrapli_netconf/driver/sync_driver.py", line 117, in open
    self.channel.channel_authenticate_netconf(
  File "/home/admin/.local/share/virtualenvs/Dev-jffJP19G/lib/python3.9/site-packages/scrapli/decorators.py", line 223, in decorate
    return _multiprocessing_timeout(
  File "/home/admin/.local/share/virtualenvs/Dev-jffJP19G/lib/python3.9/site-packages/scrapli/decorators.py", line 114, in _multiprocessing_timeout
    return future.result()
  File "/usr/lib64/python3.9/concurrent/futures/_base.py", line 439, in result
    return self.__get_result()
  File "/usr/lib64/python3.9/concurrent/futures/_base.py", line 391, in __get_result
    raise self._exception
  File "/usr/lib64/python3.9/concurrent/futures/thread.py", line 58, in run
    result = self.fn(*self.args, **self.kwargs)
  File "/home/admin/.local/share/virtualenvs/Dev-jffJP19G/lib/python3.9/site-packages/scrapli_netconf/channel/sync_channel.py", line 107, in channel_authenticate_netconf
    self._ssh_message_handler(output=authenticate_buf)
  File "/home/admin/.local/share/virtualenvs/Dev-jffJP19G/lib/python3.9/site-packages/scrapli/channel/base_channel.py", line 476, in _ssh_message_handler
    raise ScrapliAuthenticationFailed(msg)
scrapli.exceptions.ScrapliAuthenticationFailed: Could not resolve address for host

2024-06-24 19:38:45,160 -  nornir.core -     INFO -        run() - Running task 'netconf_edit_config' with args {'config': '<config>\n    <interfaces xmlns="urn:ietf:params:xml:ns:yang:ietf-interfaces">\n        <interface>\n            <name>Ethernet1</name>\n            <description>scrapli was here!</description>\n        </interface>\n    </interfaces>\n</config>'} on 1 hosts
2024-06-24 19:38:45,442 - nornir.core.task -    ERROR -      start() - Host 'R2': task 'netconf_edit_config' failed with traceback:
Traceback (most recent call last):
  File "/home/admin/.local/share/virtualenvs/Dev-jffJP19G/lib/python3.9/site-packages/nornir/core/task.py", line 99, in start
    r = self.task(self, **self.params)
  File "/home/admin/.local/share/virtualenvs/Dev-jffJP19G/lib/python3.9/site-packages/nornir_scrapli/tasks/netconf/edit_config.py", line 38, in netconf_edit_config
    scrapli_conn = task.host.get_connection("scrapli_netconf", task.nornir.config)
  File "/home/admin/.local/share/virtualenvs/Dev-jffJP19G/lib/python3.9/site-packages/nornir/core/inventory.py", line 494, in get_connection
    self.open_connection(
  File "/home/admin/.local/share/virtualenvs/Dev-jffJP19G/lib/python3.9/site-packages/nornir/core/inventory.py", line 546, in open_connection
    conn_obj.open(
  File "/home/admin/.local/share/virtualenvs/Dev-jffJP19G/lib/python3.9/site-packages/nornir_scrapli/connection.py", line 287, in open
    connection.open()
  File "/home/admin/.local/share/virtualenvs/Dev-jffJP19G/lib/python3.9/site-packages/scrapli_netconf/driver/sync_driver.py", line 117, in open
    self.channel.channel_authenticate_netconf(
  File "/home/admin/.local/share/virtualenvs/Dev-jffJP19G/lib/python3.9/site-packages/scrapli/decorators.py", line 223, in decorate
    return _multiprocessing_timeout(
  File "/home/admin/.local/share/virtualenvs/Dev-jffJP19G/lib/python3.9/site-packages/scrapli/decorators.py", line 114, in _multiprocessing_timeout
    return future.result()
  File "/usr/lib64/python3.9/concurrent/futures/_base.py", line 439, in result
    return self.__get_result()
  File "/usr/lib64/python3.9/concurrent/futures/_base.py", line 391, in __get_result
    raise self._exception
  File "/usr/lib64/python3.9/concurrent/futures/thread.py", line 58, in run
    result = self.fn(*self.args, **self.kwargs)
  File "/home/admin/.local/share/virtualenvs/Dev-jffJP19G/lib/python3.9/site-packages/scrapli_netconf/channel/sync_channel.py", line 107, in channel_authenticate_netconf
    self._ssh_message_handler(output=authenticate_buf)
  File "/home/admin/.local/share/virtualenvs/Dev-jffJP19G/lib/python3.9/site-packages/scrapli/channel/base_channel.py", line 476, in _ssh_message_handler
    raise ScrapliAuthenticationFailed(msg)
scrapli.exceptions.ScrapliAuthenticationFailed: Host key verification failed

2024-06-24 19:42:18,281 -  nornir.core -     INFO -        run() - Running task 'netconf_edit_config' with args {'config': '<config>\n    <interfaces xmlns="urn:ietf:params:xml:ns:yang:ietf-interfaces">\n        <interface>\n            <name>Ethernet1</name>\n            <description>scrapli was here!</description>\n        </interface>\n    </interfaces>\n</config>'} on 1 hosts
2024-06-24 19:42:18,553 - nornir.core.task -    ERROR -      start() - Host 'R2': task 'netconf_edit_config' failed with traceback:
Traceback (most recent call last):
  File "/home/admin/.local/share/virtualenvs/Dev-jffJP19G/lib/python3.9/site-packages/nornir/core/task.py", line 99, in start
    r = self.task(self, **self.params)
  File "/home/admin/.local/share/virtualenvs/Dev-jffJP19G/lib/python3.9/site-packages/nornir_scrapli/tasks/netconf/edit_config.py", line 38, in netconf_edit_config
    scrapli_conn = task.host.get_connection("scrapli_netconf", task.nornir.config)
  File "/home/admin/.local/share/virtualenvs/Dev-jffJP19G/lib/python3.9/site-packages/nornir/core/inventory.py", line 494, in get_connection
    self.open_connection(
  File "/home/admin/.local/share/virtualenvs/Dev-jffJP19G/lib/python3.9/site-packages/nornir/core/inventory.py", line 546, in open_connection
    conn_obj.open(
  File "/home/admin/.local/share/virtualenvs/Dev-jffJP19G/lib/python3.9/site-packages/nornir_scrapli/connection.py", line 287, in open
    connection.open()
  File "/home/admin/.local/share/virtualenvs/Dev-jffJP19G/lib/python3.9/site-packages/scrapli_netconf/driver/sync_driver.py", line 117, in open
    self.channel.channel_authenticate_netconf(
  File "/home/admin/.local/share/virtualenvs/Dev-jffJP19G/lib/python3.9/site-packages/scrapli/decorators.py", line 223, in decorate
    return _multiprocessing_timeout(
  File "/home/admin/.local/share/virtualenvs/Dev-jffJP19G/lib/python3.9/site-packages/scrapli/decorators.py", line 114, in _multiprocessing_timeout
    return future.result()
  File "/usr/lib64/python3.9/concurrent/futures/_base.py", line 439, in result
    return self.__get_result()
  File "/usr/lib64/python3.9/concurrent/futures/_base.py", line 391, in __get_result
    raise self._exception
  File "/usr/lib64/python3.9/concurrent/futures/thread.py", line 58, in run
    result = self.fn(*self.args, **self.kwargs)
  File "/home/admin/.local/share/virtualenvs/Dev-jffJP19G/lib/python3.9/site-packages/scrapli_netconf/channel/sync_channel.py", line 107, in channel_authenticate_netconf
    self._ssh_message_handler(output=authenticate_buf)
  File "/home/admin/.local/share/virtualenvs/Dev-jffJP19G/lib/python3.9/site-packages/scrapli/channel/base_channel.py", line 476, in _ssh_message_handler
    raise ScrapliAuthenticationFailed(msg)
scrapli.exceptions.ScrapliAuthenticationFailed: Host key verification failed

2024-06-24 19:42:54,476 -  nornir.core -     INFO -        run() - Running task 'netconf_edit_config' with args {'config': '<config>\n    <interfaces xmlns="urn:ietf:params:xml:ns:yang:ietf-interfaces">\n        <interface>\n            <name>Ethernet1</name>\n            <description>scrapli was here!</description>\n        </interface>\n    </interfaces>\n</config>'} on 1 hosts
2024-06-24 19:42:54,729 - nornir.core.task -    ERROR -      start() - Host 'R2': task 'netconf_edit_config' failed with traceback:
Traceback (most recent call last):
  File "/home/admin/.local/share/virtualenvs/Dev-jffJP19G/lib/python3.9/site-packages/nornir/core/task.py", line 99, in start
    r = self.task(self, **self.params)
  File "/home/admin/.local/share/virtualenvs/Dev-jffJP19G/lib/python3.9/site-packages/nornir_scrapli/tasks/netconf/edit_config.py", line 38, in netconf_edit_config
    scrapli_conn = task.host.get_connection("scrapli_netconf", task.nornir.config)
  File "/home/admin/.local/share/virtualenvs/Dev-jffJP19G/lib/python3.9/site-packages/nornir/core/inventory.py", line 494, in get_connection
    self.open_connection(
  File "/home/admin/.local/share/virtualenvs/Dev-jffJP19G/lib/python3.9/site-packages/nornir/core/inventory.py", line 546, in open_connection
    conn_obj.open(
  File "/home/admin/.local/share/virtualenvs/Dev-jffJP19G/lib/python3.9/site-packages/nornir_scrapli/connection.py", line 287, in open
    connection.open()
  File "/home/admin/.local/share/virtualenvs/Dev-jffJP19G/lib/python3.9/site-packages/scrapli_netconf/driver/sync_driver.py", line 117, in open
    self.channel.channel_authenticate_netconf(
  File "/home/admin/.local/share/virtualenvs/Dev-jffJP19G/lib/python3.9/site-packages/scrapli/decorators.py", line 223, in decorate
    return _multiprocessing_timeout(
  File "/home/admin/.local/share/virtualenvs/Dev-jffJP19G/lib/python3.9/site-packages/scrapli/decorators.py", line 114, in _multiprocessing_timeout
    return future.result()
  File "/usr/lib64/python3.9/concurrent/futures/_base.py", line 439, in result
    return self.__get_result()
  File "/usr/lib64/python3.9/concurrent/futures/_base.py", line 391, in __get_result
    raise self._exception
  File "/usr/lib64/python3.9/concurrent/futures/thread.py", line 58, in run
    result = self.fn(*self.args, **self.kwargs)
  File "/home/admin/.local/share/virtualenvs/Dev-jffJP19G/lib/python3.9/site-packages/scrapli_netconf/channel/sync_channel.py", line 107, in channel_authenticate_netconf
    self._ssh_message_handler(output=authenticate_buf)
  File "/home/admin/.local/share/virtualenvs/Dev-jffJP19G/lib/python3.9/site-packages/scrapli/channel/base_channel.py", line 476, in _ssh_message_handler
    raise ScrapliAuthenticationFailed(msg)
scrapli.exceptions.ScrapliAuthenticationFailed: Host key verification failed

2024-06-24 19:45:29,169 -  nornir.core -     INFO -        run() - Running task 'netconf_edit_config' with args {'config': '<config>\n    <interfaces xmlns="urn:ietf:params:xml:ns:yang:ietf-interfaces">\n        <interface>\n            <name>Ethernet1</name>\n            <description>scrapli was here!</description>\n        </interface>\n    </interfaces>\n</config>'} on 1 hosts
2024-06-24 19:45:29,428 - nornir.core.task -    ERROR -      start() - Host 'R2': task 'netconf_edit_config' failed with traceback:
Traceback (most recent call last):
  File "/home/admin/.local/share/virtualenvs/Dev-jffJP19G/lib/python3.9/site-packages/nornir/core/task.py", line 99, in start
    r = self.task(self, **self.params)
  File "/home/admin/.local/share/virtualenvs/Dev-jffJP19G/lib/python3.9/site-packages/nornir_scrapli/tasks/netconf/edit_config.py", line 38, in netconf_edit_config
    scrapli_conn = task.host.get_connection("scrapli_netconf", task.nornir.config)
  File "/home/admin/.local/share/virtualenvs/Dev-jffJP19G/lib/python3.9/site-packages/nornir/core/inventory.py", line 494, in get_connection
    self.open_connection(
  File "/home/admin/.local/share/virtualenvs/Dev-jffJP19G/lib/python3.9/site-packages/nornir/core/inventory.py", line 546, in open_connection
    conn_obj.open(
  File "/home/admin/.local/share/virtualenvs/Dev-jffJP19G/lib/python3.9/site-packages/nornir_scrapli/connection.py", line 287, in open
    connection.open()
  File "/home/admin/.local/share/virtualenvs/Dev-jffJP19G/lib/python3.9/site-packages/scrapli_netconf/driver/sync_driver.py", line 117, in open
    self.channel.channel_authenticate_netconf(
  File "/home/admin/.local/share/virtualenvs/Dev-jffJP19G/lib/python3.9/site-packages/scrapli/decorators.py", line 223, in decorate
    return _multiprocessing_timeout(
  File "/home/admin/.local/share/virtualenvs/Dev-jffJP19G/lib/python3.9/site-packages/scrapli/decorators.py", line 114, in _multiprocessing_timeout
    return future.result()
  File "/usr/lib64/python3.9/concurrent/futures/_base.py", line 439, in result
    return self.__get_result()
  File "/usr/lib64/python3.9/concurrent/futures/_base.py", line 391, in __get_result
    raise self._exception
  File "/usr/lib64/python3.9/concurrent/futures/thread.py", line 58, in run
    result = self.fn(*self.args, **self.kwargs)
  File "/home/admin/.local/share/virtualenvs/Dev-jffJP19G/lib/python3.9/site-packages/scrapli_netconf/channel/sync_channel.py", line 107, in channel_authenticate_netconf
    self._ssh_message_handler(output=authenticate_buf)
  File "/home/admin/.local/share/virtualenvs/Dev-jffJP19G/lib/python3.9/site-packages/scrapli/channel/base_channel.py", line 476, in _ssh_message_handler
    raise ScrapliAuthenticationFailed(msg)
scrapli.exceptions.ScrapliAuthenticationFailed: Host key verification failed

2024-06-24 19:45:31,895 -  nornir.core -     INFO -        run() - Running task 'netconf_edit_config' with args {'config': '<config>\n    <interfaces xmlns="urn:ietf:params:xml:ns:yang:ietf-interfaces">\n        <interface>\n            <name>Ethernet1</name>\n            <description>scrapli was here!</description>\n        </interface>\n    </interfaces>\n</config>'} on 1 hosts
2024-06-24 19:45:32,154 - nornir.core.task -    ERROR -      start() - Host 'R2': task 'netconf_edit_config' failed with traceback:
Traceback (most recent call last):
  File "/home/admin/.local/share/virtualenvs/Dev-jffJP19G/lib/python3.9/site-packages/nornir/core/task.py", line 99, in start
    r = self.task(self, **self.params)
  File "/home/admin/.local/share/virtualenvs/Dev-jffJP19G/lib/python3.9/site-packages/nornir_scrapli/tasks/netconf/edit_config.py", line 38, in netconf_edit_config
    scrapli_conn = task.host.get_connection("scrapli_netconf", task.nornir.config)
  File "/home/admin/.local/share/virtualenvs/Dev-jffJP19G/lib/python3.9/site-packages/nornir/core/inventory.py", line 494, in get_connection
    self.open_connection(
  File "/home/admin/.local/share/virtualenvs/Dev-jffJP19G/lib/python3.9/site-packages/nornir/core/inventory.py", line 546, in open_connection
    conn_obj.open(
  File "/home/admin/.local/share/virtualenvs/Dev-jffJP19G/lib/python3.9/site-packages/nornir_scrapli/connection.py", line 287, in open
    connection.open()
  File "/home/admin/.local/share/virtualenvs/Dev-jffJP19G/lib/python3.9/site-packages/scrapli_netconf/driver/sync_driver.py", line 117, in open
    self.channel.channel_authenticate_netconf(
  File "/home/admin/.local/share/virtualenvs/Dev-jffJP19G/lib/python3.9/site-packages/scrapli/decorators.py", line 223, in decorate
    return _multiprocessing_timeout(
  File "/home/admin/.local/share/virtualenvs/Dev-jffJP19G/lib/python3.9/site-packages/scrapli/decorators.py", line 114, in _multiprocessing_timeout
    return future.result()
  File "/usr/lib64/python3.9/concurrent/futures/_base.py", line 439, in result
    return self.__get_result()
  File "/usr/lib64/python3.9/concurrent/futures/_base.py", line 391, in __get_result
    raise self._exception
  File "/usr/lib64/python3.9/concurrent/futures/thread.py", line 58, in run
    result = self.fn(*self.args, **self.kwargs)
  File "/home/admin/.local/share/virtualenvs/Dev-jffJP19G/lib/python3.9/site-packages/scrapli_netconf/channel/sync_channel.py", line 107, in channel_authenticate_netconf
    self._ssh_message_handler(output=authenticate_buf)
  File "/home/admin/.local/share/virtualenvs/Dev-jffJP19G/lib/python3.9/site-packages/scrapli/channel/base_channel.py", line 476, in _ssh_message_handler
    raise ScrapliAuthenticationFailed(msg)
scrapli.exceptions.ScrapliAuthenticationFailed: Host key verification failed

2024-06-24 19:45:33,999 -  nornir.core -     INFO -        run() - Running task 'netconf_edit_config' with args {'config': '<config>\n    <interfaces xmlns="urn:ietf:params:xml:ns:yang:ietf-interfaces">\n        <interface>\n            <name>Ethernet1</name>\n            <description>scrapli was here!</description>\n        </interface>\n    </interfaces>\n</config>'} on 1 hosts
2024-06-24 19:45:34,279 - nornir.core.task -    ERROR -      start() - Host 'R2': task 'netconf_edit_config' failed with traceback:
Traceback (most recent call last):
  File "/home/admin/.local/share/virtualenvs/Dev-jffJP19G/lib/python3.9/site-packages/nornir/core/task.py", line 99, in start
    r = self.task(self, **self.params)
  File "/home/admin/.local/share/virtualenvs/Dev-jffJP19G/lib/python3.9/site-packages/nornir_scrapli/tasks/netconf/edit_config.py", line 38, in netconf_edit_config
    scrapli_conn = task.host.get_connection("scrapli_netconf", task.nornir.config)
  File "/home/admin/.local/share/virtualenvs/Dev-jffJP19G/lib/python3.9/site-packages/nornir/core/inventory.py", line 494, in get_connection
    self.open_connection(
  File "/home/admin/.local/share/virtualenvs/Dev-jffJP19G/lib/python3.9/site-packages/nornir/core/inventory.py", line 546, in open_connection
    conn_obj.open(
  File "/home/admin/.local/share/virtualenvs/Dev-jffJP19G/lib/python3.9/site-packages/nornir_scrapli/connection.py", line 287, in open
    connection.open()
  File "/home/admin/.local/share/virtualenvs/Dev-jffJP19G/lib/python3.9/site-packages/scrapli_netconf/driver/sync_driver.py", line 117, in open
    self.channel.channel_authenticate_netconf(
  File "/home/admin/.local/share/virtualenvs/Dev-jffJP19G/lib/python3.9/site-packages/scrapli/decorators.py", line 223, in decorate
    return _multiprocessing_timeout(
  File "/home/admin/.local/share/virtualenvs/Dev-jffJP19G/lib/python3.9/site-packages/scrapli/decorators.py", line 114, in _multiprocessing_timeout
    return future.result()
  File "/usr/lib64/python3.9/concurrent/futures/_base.py", line 439, in result
    return self.__get_result()
  File "/usr/lib64/python3.9/concurrent/futures/_base.py", line 391, in __get_result
    raise self._exception
  File "/usr/lib64/python3.9/concurrent/futures/thread.py", line 58, in run
    result = self.fn(*self.args, **self.kwargs)
  File "/home/admin/.local/share/virtualenvs/Dev-jffJP19G/lib/python3.9/site-packages/scrapli_netconf/channel/sync_channel.py", line 107, in channel_authenticate_netconf
    self._ssh_message_handler(output=authenticate_buf)
  File "/home/admin/.local/share/virtualenvs/Dev-jffJP19G/lib/python3.9/site-packages/scrapli/channel/base_channel.py", line 476, in _ssh_message_handler
    raise ScrapliAuthenticationFailed(msg)
scrapli.exceptions.ScrapliAuthenticationFailed: Host key verification failed

2024-06-24 19:46:14,655 -  nornir.core -     INFO -        run() - Running task 'netconf_edit_config' with args {'config': '<config>\n    <interfaces xmlns="urn:ietf:params:xml:ns:yang:ietf-interfaces">\n        <interface>\n            <name>Ethernet1</name>\n            <description>scrapli was here!</description>\n        </interface>\n    </interfaces>\n</config>'} on 1 hosts
2024-06-24 19:46:14,911 - nornir.core.task -    ERROR -      start() - Host 'R2': task 'netconf_edit_config' failed with traceback:
Traceback (most recent call last):
  File "/home/admin/.local/share/virtualenvs/Dev-jffJP19G/lib/python3.9/site-packages/nornir/core/task.py", line 99, in start
    r = self.task(self, **self.params)
  File "/home/admin/.local/share/virtualenvs/Dev-jffJP19G/lib/python3.9/site-packages/nornir_scrapli/tasks/netconf/edit_config.py", line 38, in netconf_edit_config
    scrapli_conn = task.host.get_connection("scrapli_netconf", task.nornir.config)
  File "/home/admin/.local/share/virtualenvs/Dev-jffJP19G/lib/python3.9/site-packages/nornir/core/inventory.py", line 494, in get_connection
    self.open_connection(
  File "/home/admin/.local/share/virtualenvs/Dev-jffJP19G/lib/python3.9/site-packages/nornir/core/inventory.py", line 546, in open_connection
    conn_obj.open(
  File "/home/admin/.local/share/virtualenvs/Dev-jffJP19G/lib/python3.9/site-packages/nornir_scrapli/connection.py", line 287, in open
    connection.open()
  File "/home/admin/.local/share/virtualenvs/Dev-jffJP19G/lib/python3.9/site-packages/scrapli_netconf/driver/sync_driver.py", line 117, in open
    self.channel.channel_authenticate_netconf(
  File "/home/admin/.local/share/virtualenvs/Dev-jffJP19G/lib/python3.9/site-packages/scrapli/decorators.py", line 223, in decorate
    return _multiprocessing_timeout(
  File "/home/admin/.local/share/virtualenvs/Dev-jffJP19G/lib/python3.9/site-packages/scrapli/decorators.py", line 114, in _multiprocessing_timeout
    return future.result()
  File "/usr/lib64/python3.9/concurrent/futures/_base.py", line 439, in result
    return self.__get_result()
  File "/usr/lib64/python3.9/concurrent/futures/_base.py", line 391, in __get_result
    raise self._exception
  File "/usr/lib64/python3.9/concurrent/futures/thread.py", line 58, in run
    result = self.fn(*self.args, **self.kwargs)
  File "/home/admin/.local/share/virtualenvs/Dev-jffJP19G/lib/python3.9/site-packages/scrapli_netconf/channel/sync_channel.py", line 107, in channel_authenticate_netconf
    self._ssh_message_handler(output=authenticate_buf)
  File "/home/admin/.local/share/virtualenvs/Dev-jffJP19G/lib/python3.9/site-packages/scrapli/channel/base_channel.py", line 476, in _ssh_message_handler
    raise ScrapliAuthenticationFailed(msg)
scrapli.exceptions.ScrapliAuthenticationFailed: Host key verification failed

2024-06-24 19:46:17,377 -  nornir.core -     INFO -        run() - Running task 'netconf_edit_config' with args {'config': '<config>\n    <interfaces xmlns="urn:ietf:params:xml:ns:yang:ietf-interfaces">\n        <interface>\n            <name>Ethernet1</name>\n            <description>scrapli was here!</description>\n        </interface>\n    </interfaces>\n</config>'} on 1 hosts
2024-06-24 19:46:17,628 - nornir.core.task -    ERROR -      start() - Host 'R2': task 'netconf_edit_config' failed with traceback:
Traceback (most recent call last):
  File "/home/admin/.local/share/virtualenvs/Dev-jffJP19G/lib/python3.9/site-packages/nornir/core/task.py", line 99, in start
    r = self.task(self, **self.params)
  File "/home/admin/.local/share/virtualenvs/Dev-jffJP19G/lib/python3.9/site-packages/nornir_scrapli/tasks/netconf/edit_config.py", line 38, in netconf_edit_config
    scrapli_conn = task.host.get_connection("scrapli_netconf", task.nornir.config)
  File "/home/admin/.local/share/virtualenvs/Dev-jffJP19G/lib/python3.9/site-packages/nornir/core/inventory.py", line 494, in get_connection
    self.open_connection(
  File "/home/admin/.local/share/virtualenvs/Dev-jffJP19G/lib/python3.9/site-packages/nornir/core/inventory.py", line 546, in open_connection
    conn_obj.open(
  File "/home/admin/.local/share/virtualenvs/Dev-jffJP19G/lib/python3.9/site-packages/nornir_scrapli/connection.py", line 287, in open
    connection.open()
  File "/home/admin/.local/share/virtualenvs/Dev-jffJP19G/lib/python3.9/site-packages/scrapli_netconf/driver/sync_driver.py", line 117, in open
    self.channel.channel_authenticate_netconf(
  File "/home/admin/.local/share/virtualenvs/Dev-jffJP19G/lib/python3.9/site-packages/scrapli/decorators.py", line 223, in decorate
    return _multiprocessing_timeout(
  File "/home/admin/.local/share/virtualenvs/Dev-jffJP19G/lib/python3.9/site-packages/scrapli/decorators.py", line 114, in _multiprocessing_timeout
    return future.result()
  File "/usr/lib64/python3.9/concurrent/futures/_base.py", line 439, in result
    return self.__get_result()
  File "/usr/lib64/python3.9/concurrent/futures/_base.py", line 391, in __get_result
    raise self._exception
  File "/usr/lib64/python3.9/concurrent/futures/thread.py", line 58, in run
    result = self.fn(*self.args, **self.kwargs)
  File "/home/admin/.local/share/virtualenvs/Dev-jffJP19G/lib/python3.9/site-packages/scrapli_netconf/channel/sync_channel.py", line 107, in channel_authenticate_netconf
    self._ssh_message_handler(output=authenticate_buf)
  File "/home/admin/.local/share/virtualenvs/Dev-jffJP19G/lib/python3.9/site-packages/scrapli/channel/base_channel.py", line 476, in _ssh_message_handler
    raise ScrapliAuthenticationFailed(msg)
scrapli.exceptions.ScrapliAuthenticationFailed: Host key verification failed

2024-06-24 19:47:06,212 -  nornir.core -     INFO -        run() - Running task 'netconf_edit_config' with args {'config': '<config>\n    <interfaces xmlns="urn:ietf:params:xml:ns:yang:ietf-interfaces">\n        <interface>\n            <name>Ethernet1</name>\n            <description>scrapli was here!</description>\n        </interface>\n    </interfaces>\n</config>'} on 1 hosts
2024-06-24 19:47:06,469 - nornir.core.task -    ERROR -      start() - Host 'R2': task 'netconf_edit_config' failed with traceback:
Traceback (most recent call last):
  File "/home/admin/.local/share/virtualenvs/Dev-jffJP19G/lib/python3.9/site-packages/nornir/core/task.py", line 99, in start
    r = self.task(self, **self.params)
  File "/home/admin/.local/share/virtualenvs/Dev-jffJP19G/lib/python3.9/site-packages/nornir_scrapli/tasks/netconf/edit_config.py", line 38, in netconf_edit_config
    scrapli_conn = task.host.get_connection("scrapli_netconf", task.nornir.config)
  File "/home/admin/.local/share/virtualenvs/Dev-jffJP19G/lib/python3.9/site-packages/nornir/core/inventory.py", line 494, in get_connection
    self.open_connection(
  File "/home/admin/.local/share/virtualenvs/Dev-jffJP19G/lib/python3.9/site-packages/nornir/core/inventory.py", line 546, in open_connection
    conn_obj.open(
  File "/home/admin/.local/share/virtualenvs/Dev-jffJP19G/lib/python3.9/site-packages/nornir_scrapli/connection.py", line 287, in open
    connection.open()
  File "/home/admin/.local/share/virtualenvs/Dev-jffJP19G/lib/python3.9/site-packages/scrapli_netconf/driver/sync_driver.py", line 117, in open
    self.channel.channel_authenticate_netconf(
  File "/home/admin/.local/share/virtualenvs/Dev-jffJP19G/lib/python3.9/site-packages/scrapli/decorators.py", line 223, in decorate
    return _multiprocessing_timeout(
  File "/home/admin/.local/share/virtualenvs/Dev-jffJP19G/lib/python3.9/site-packages/scrapli/decorators.py", line 114, in _multiprocessing_timeout
    return future.result()
  File "/usr/lib64/python3.9/concurrent/futures/_base.py", line 439, in result
    return self.__get_result()
  File "/usr/lib64/python3.9/concurrent/futures/_base.py", line 391, in __get_result
    raise self._exception
  File "/usr/lib64/python3.9/concurrent/futures/thread.py", line 58, in run
    result = self.fn(*self.args, **self.kwargs)
  File "/home/admin/.local/share/virtualenvs/Dev-jffJP19G/lib/python3.9/site-packages/scrapli_netconf/channel/sync_channel.py", line 107, in channel_authenticate_netconf
    self._ssh_message_handler(output=authenticate_buf)
  File "/home/admin/.local/share/virtualenvs/Dev-jffJP19G/lib/python3.9/site-packages/scrapli/channel/base_channel.py", line 476, in _ssh_message_handler
    raise ScrapliAuthenticationFailed(msg)
scrapli.exceptions.ScrapliAuthenticationFailed: Host key verification failed

2024-06-24 19:48:49,584 -  nornir.core -     INFO -        run() - Running task 'netconf_edit_config' with args {'config': '<config>\n    <interfaces xmlns="urn:ietf:params:xml:ns:yang:ietf-interfaces">\n        <interface>\n            <name>Ethernet1</name>\n            <description>scrapli was here!</description>\n        </interface>\n    </interfaces>\n</config>'} on 1 hosts
2024-06-24 19:49:22,501 -  nornir.core -     INFO -        run() - Running task 'netconf_edit_config' with args {'config': '<config>\n    <interfaces xmlns="urn:ietf:params:xml:ns:yang:ietf-interfaces">\n        <interface>\n            <name>Ethernet1</name>\n            <description>scrapli was here!</description>\n        </interface>\n    </interfaces>\n</config>'} on 1 hosts
2024-06-24 22:28:16,853 -  nornir.core -     INFO -        run() - Running task 'netconf_get_config' with args {} on 1 hosts
2024-06-24 22:29:48,417 -  nornir.core -     INFO -        run() - Running task 'netconf_get_config' with args {'source': 'running'} on 1 hosts
2024-06-24 22:35:18,253 -  nornir.core -     INFO -        run() - Running task 'netconf_get_config' with args {'source': 'running'} on 1 hosts
2024-06-24 22:37:37,712 -  nornir.core -     INFO -        run() - Running task 'get_data' with args {} on 1 hosts
2024-06-24 22:38:19,810 -  nornir.core -     INFO -        run() - Running task 'get_data' with args {} on 1 hosts
2024-06-24 22:38:44,332 -  nornir.core -     INFO -        run() - Running task 'get_data' with args {} on 1 hosts
2024-06-24 22:40:43,455 -  nornir.core -     INFO -        run() - Running task 'get_config' with args {} on 1 hosts
2024-06-24 22:43:26,623 -  nornir.core -     INFO -        run() - Running task 'get_config' with args {} on 1 hosts
2024-06-24 22:44:18,884 -  nornir.core -     INFO -        run() - Running task 'get_config' with args {} on 1 hosts
2024-06-24 22:46:18,519 -  nornir.core -     INFO -        run() - Running task 'get_config' with args {} on 1 hosts
2024-06-24 22:46:22,301 -  nornir.core -     INFO -        run() - Running task 'get_config' with args {} on 1 hosts
2024-06-24 23:32:02,123 -  nornir.core -     INFO -        run() - Running task 'get_config' with args {} on 1 hosts
2024-06-24 23:32:02,125 - nornir.core.task -    ERROR -      start() - Host 'leaf1': task 'netconf_get' failed with traceback:
Traceback (most recent call last):
  File "/home/admin/.local/share/virtualenvs/Dev-jffJP19G/lib/python3.9/site-packages/nornir/core/task.py", line 99, in start
    r = self.task(self, **self.params)
TypeError: netconf_get() got an unexpected keyword argument 'source'

2024-06-24 23:32:02,126 - nornir.core.task -    ERROR -      start() - Host 'leaf1': task 'get_config' failed with traceback:
Traceback (most recent call last):
  File "/home/admin/.local/share/virtualenvs/Dev-jffJP19G/lib/python3.9/site-packages/nornir/core/task.py", line 99, in start
    r = self.task(self, **self.params)
  File "/home/admin/Dev/arista_vxlan_project/python_scripts/vlan_oper.py", line 11, in get_config
    result = task.run(task=netconf_get, source="running")
  File "/home/admin/.local/share/virtualenvs/Dev-jffJP19G/lib/python3.9/site-packages/nornir/core/task.py", line 174, in run
    raise NornirSubTaskError(task=run_task, result=r)
nornir.core.exceptions.NornirSubTaskError: Subtask: netconf_get (failed)


2024-06-24 23:32:28,338 -  nornir.core -     INFO -        run() - Running task 'get_config' with args {} on 1 hosts
2024-06-24 23:32:28,340 - nornir.core.task -    ERROR -      start() - Host 'leaf1': task 'netconf_get' failed with traceback:
Traceback (most recent call last):
  File "/home/admin/.local/share/virtualenvs/Dev-jffJP19G/lib/python3.9/site-packages/nornir/core/task.py", line 99, in start
    r = self.task(self, **self.params)
TypeError: netconf_get() missing 1 required positional argument: 'filter_'

2024-06-24 23:32:28,340 - nornir.core.task -    ERROR -      start() - Host 'leaf1': task 'get_config' failed with traceback:
Traceback (most recent call last):
  File "/home/admin/.local/share/virtualenvs/Dev-jffJP19G/lib/python3.9/site-packages/nornir/core/task.py", line 99, in start
    r = self.task(self, **self.params)
  File "/home/admin/Dev/arista_vxlan_project/python_scripts/vlan_oper.py", line 11, in get_config
    result = task.run(task=netconf_get)
  File "/home/admin/.local/share/virtualenvs/Dev-jffJP19G/lib/python3.9/site-packages/nornir/core/task.py", line 174, in run
    raise NornirSubTaskError(task=run_task, result=r)
nornir.core.exceptions.NornirSubTaskError: Subtask: netconf_get (failed)


2024-06-24 23:33:43,179 -  nornir.core -     INFO -        run() - Running task 'get_config' with args {} on 1 hosts
2024-06-24 23:33:43,182 - nornir.core.task -    ERROR -      start() - Host 'leaf1': task 'netconf_get' failed with traceback:
Traceback (most recent call last):
  File "/home/admin/.local/share/virtualenvs/Dev-jffJP19G/lib/python3.9/site-packages/nornir/core/task.py", line 99, in start
    r = self.task(self, **self.params)
TypeError: netconf_get() got an unexpected keyword argument 'filter'

2024-06-24 23:33:43,183 - nornir.core.task -    ERROR -      start() - Host 'leaf1': task 'get_config' failed with traceback:
Traceback (most recent call last):
  File "/home/admin/.local/share/virtualenvs/Dev-jffJP19G/lib/python3.9/site-packages/nornir/core/task.py", line 99, in start
    r = self.task(self, **self.params)
  File "/home/admin/Dev/arista_vxlan_project/python_scripts/vlan_oper.py", line 11, in get_config
    result = task.run(task=netconf_get, filter='/native')
  File "/home/admin/.local/share/virtualenvs/Dev-jffJP19G/lib/python3.9/site-packages/nornir/core/task.py", line 174, in run
    raise NornirSubTaskError(task=run_task, result=r)
nornir.core.exceptions.NornirSubTaskError: Subtask: netconf_get (failed)


2024-06-24 23:34:32,776 -  nornir.core -     INFO -        run() - Running task 'get_config' with args {} on 1 hosts
2024-06-24 23:35:32,837 -  nornir.core -     INFO -        run() - Running task 'get_data' with args {} on 1 hosts
2024-06-24 23:43:43,733 -  nornir.core -     INFO -        run() - Running task 'inventory_usernames' with args {} on 1 hosts
2024-06-24 23:45:20,114 -  nornir.core -     INFO -        run() - Running task 'inventory_usernames' with args {} on 1 hosts
2024-06-24 23:45:45,965 -  nornir.core -     INFO -        run() - Running task 'inventory_usernames' with args {} on 1 hosts
2024-06-24 23:49:27,608 -  nornir.core -     INFO -        run() - Running task 'get_config' with args {} on 1 hosts
2024-06-25 18:46:23,914 -  nornir.core -     INFO -        run() - Running task 'send_command' with args {'command': 'show version'} on 1 hosts
2024-06-25 18:46:42,564 -  nornir.core -     INFO -        run() - Running task 'send_command' with args {'command': 'show ip int brief'} on 1 hosts
2024-06-25 18:47:06,042 -  nornir.core -     INFO -        run() - Running task 'send_command' with args {'command': 'show ip int brief'} on 1 hosts
2024-06-25 18:47:30,904 -  nornir.core -     INFO -        run() - Running task 'send_command' with args {'command': 'show ip int brief'} on 1 hosts
2024-06-25 18:49:39,047 -  nornir.core -     INFO -        run() - Running task 'send_command' with args {'command': 'show ip int brief'} on 2 hosts
2024-06-25 18:49:50,387 -  nornir.core -     INFO -        run() - Running task 'send_command' with args {'command': 'show ip int brief'} on 2 hosts
2024-06-25 18:49:56,008 -  nornir.core -     INFO -        run() - Running task 'send_command' with args {'command': 'show ip int brief'} on 2 hosts
2024-06-25 18:50:38,965 -  nornir.core -     INFO -        run() - Running task 'send_command' with args {'command': 'show ip int brief'} on 2 hosts
2024-06-25 18:51:35,238 -  nornir.core -     INFO -        run() - Running task 'send_command' with args {'command': 'show ip int brief'} on 2 hosts
2024-06-25 19:05:15,341 -  nornir.core -     INFO -        run() - Running task 'send_command' with args {'command': 'show ip int brief'} on 3 hosts
2024-06-25 19:05:15,374 - nornir.core.task -    ERROR -      start() - Host 'spine1': task 'send_command' failed with traceback:
Traceback (most recent call last):
  File "/home/admin/.local/share/virtualenvs/Dev-jffJP19G/lib/python3.9/site-packages/scrapli/factory.py", line 159, in _get_community_platform_details
    scrapli_community_platform = importlib.import_module(
  File "/usr/lib64/python3.9/importlib/__init__.py", line 127, in import_module
    return _bootstrap._gcd_import(name[level:], package, level)
  File "<frozen importlib._bootstrap>", line 1030, in _gcd_import
  File "<frozen importlib._bootstrap>", line 1007, in _find_and_load
  File "<frozen importlib._bootstrap>", line 984, in _find_and_load_unlocked
ModuleNotFoundError: No module named 'scrapli_community.ios-xe'

The above exception was the direct cause of the following exception:

Traceback (most recent call last):
  File "/home/admin/.local/share/virtualenvs/Dev-jffJP19G/lib/python3.9/site-packages/nornir_scrapli/connection.py", line 98, in open
    connection = Scrapli(**parameters, platform=final_platform)
  File "/home/admin/.local/share/virtualenvs/Dev-jffJP19G/lib/python3.9/site-packages/scrapli/factory.py", line 507, in __new__
    final_driver, additional_kwargs = cls._get_driver(platform=platform, variant=variant)
  File "/home/admin/.local/share/virtualenvs/Dev-jffJP19G/lib/python3.9/site-packages/scrapli/factory.py", line 328, in _get_driver
    final_driver, additional_kwargs = cls._get_community_driver(
  File "/home/admin/.local/share/virtualenvs/Dev-jffJP19G/lib/python3.9/site-packages/scrapli/factory.py", line 290, in _get_community_driver
    platform_details = _get_community_platform_details(
  File "/home/admin/.local/share/virtualenvs/Dev-jffJP19G/lib/python3.9/site-packages/scrapli/factory.py", line 170, in _get_community_platform_details
    raise ScrapliModuleNotFound(warning) from exc
scrapli.exceptions.ScrapliModuleNotFound: 

******************************************************** Module not found! ********************************************************
Scrapli Community platform 'ios-xe` not found!
To resolve this issue, ensure you have the correct platform name, and that a scrapli  community platform of that name exists!
***********************************************************************************************************************************


The above exception was the direct cause of the following exception:

Traceback (most recent call last):
  File "/home/admin/.local/share/virtualenvs/Dev-jffJP19G/lib/python3.9/site-packages/nornir/core/task.py", line 99, in start
    r = self.task(self, **self.params)
  File "/home/admin/.local/share/virtualenvs/Dev-jffJP19G/lib/python3.9/site-packages/nornir_scrapli/tasks/core/send_command.py", line 36, in send_command
    scrapli_conn = task.host.get_connection("scrapli", task.nornir.config)
  File "/home/admin/.local/share/virtualenvs/Dev-jffJP19G/lib/python3.9/site-packages/nornir/core/inventory.py", line 494, in get_connection
    self.open_connection(
  File "/home/admin/.local/share/virtualenvs/Dev-jffJP19G/lib/python3.9/site-packages/nornir/core/inventory.py", line 546, in open_connection
    conn_obj.open(
  File "/home/admin/.local/share/virtualenvs/Dev-jffJP19G/lib/python3.9/site-packages/nornir_scrapli/connection.py", line 100, in open
    raise NornirScrapliInvalidPlatform(
nornir_scrapli.exceptions.NornirScrapliInvalidPlatform: Provided platform `ios-xe` is not a valid scrapli or napalm platform, or is not a valid scrapli-community platform.

2024-06-25 19:06:14,050 -  nornir.core -     INFO -        run() - Running task 'send_command' with args {'command': 'show ip int brief'} on 3 hosts
2024-06-25 19:06:14,094 - nornir.core.task -    ERROR -      start() - Host 'spine1': task 'send_command' failed with traceback:
Traceback (most recent call last):
  File "/home/admin/.local/share/virtualenvs/Dev-jffJP19G/lib/python3.9/site-packages/scrapli/factory.py", line 159, in _get_community_platform_details
    scrapli_community_platform = importlib.import_module(
  File "/usr/lib64/python3.9/importlib/__init__.py", line 127, in import_module
    return _bootstrap._gcd_import(name[level:], package, level)
  File "<frozen importlib._bootstrap>", line 1030, in _gcd_import
  File "<frozen importlib._bootstrap>", line 1007, in _find_and_load
  File "<frozen importlib._bootstrap>", line 984, in _find_and_load_unlocked
ModuleNotFoundError: No module named 'scrapli_community.iosxe'

The above exception was the direct cause of the following exception:

Traceback (most recent call last):
  File "/home/admin/.local/share/virtualenvs/Dev-jffJP19G/lib/python3.9/site-packages/nornir_scrapli/connection.py", line 98, in open
    connection = Scrapli(**parameters, platform=final_platform)
  File "/home/admin/.local/share/virtualenvs/Dev-jffJP19G/lib/python3.9/site-packages/scrapli/factory.py", line 507, in __new__
    final_driver, additional_kwargs = cls._get_driver(platform=platform, variant=variant)
  File "/home/admin/.local/share/virtualenvs/Dev-jffJP19G/lib/python3.9/site-packages/scrapli/factory.py", line 328, in _get_driver
    final_driver, additional_kwargs = cls._get_community_driver(
  File "/home/admin/.local/share/virtualenvs/Dev-jffJP19G/lib/python3.9/site-packages/scrapli/factory.py", line 290, in _get_community_driver
    platform_details = _get_community_platform_details(
  File "/home/admin/.local/share/virtualenvs/Dev-jffJP19G/lib/python3.9/site-packages/scrapli/factory.py", line 170, in _get_community_platform_details
    raise ScrapliModuleNotFound(warning) from exc
scrapli.exceptions.ScrapliModuleNotFound: 

******************************************************** Module not found! ********************************************************
Scrapli Community platform 'iosxe` not found!
To resolve this issue, ensure you have the correct platform name, and that a scrapli  community platform of that name exists!
***********************************************************************************************************************************


The above exception was the direct cause of the following exception:

Traceback (most recent call last):
  File "/home/admin/.local/share/virtualenvs/Dev-jffJP19G/lib/python3.9/site-packages/nornir/core/task.py", line 99, in start
    r = self.task(self, **self.params)
  File "/home/admin/.local/share/virtualenvs/Dev-jffJP19G/lib/python3.9/site-packages/nornir_scrapli/tasks/core/send_command.py", line 36, in send_command
    scrapli_conn = task.host.get_connection("scrapli", task.nornir.config)
  File "/home/admin/.local/share/virtualenvs/Dev-jffJP19G/lib/python3.9/site-packages/nornir/core/inventory.py", line 494, in get_connection
    self.open_connection(
  File "/home/admin/.local/share/virtualenvs/Dev-jffJP19G/lib/python3.9/site-packages/nornir/core/inventory.py", line 546, in open_connection
    conn_obj.open(
  File "/home/admin/.local/share/virtualenvs/Dev-jffJP19G/lib/python3.9/site-packages/nornir_scrapli/connection.py", line 100, in open
    raise NornirScrapliInvalidPlatform(
nornir_scrapli.exceptions.NornirScrapliInvalidPlatform: Provided platform `iosxe` is not a valid scrapli or napalm platform, or is not a valid scrapli-community platform.

2024-06-25 19:08:00,011 -  nornir.core -     INFO -        run() - Running task 'send_command' with args {'command': 'show ip int brief'} on 3 hosts
2024-06-25 19:08:00,045 - nornir.core.task -    ERROR -      start() - Host 'spine1': task 'send_command' failed with traceback:
Traceback (most recent call last):
  File "/home/admin/.local/share/virtualenvs/Dev-jffJP19G/lib/python3.9/site-packages/scrapli/factory.py", line 159, in _get_community_platform_details
    scrapli_community_platform = importlib.import_module(
  File "/usr/lib64/python3.9/importlib/__init__.py", line 127, in import_module
    return _bootstrap._gcd_import(name[level:], package, level)
  File "<frozen importlib._bootstrap>", line 1030, in _gcd_import
  File "<frozen importlib._bootstrap>", line 1007, in _find_and_load
  File "<frozen importlib._bootstrap>", line 984, in _find_and_load_unlocked
ModuleNotFoundError: No module named 'scrapli_community.iosxe'

The above exception was the direct cause of the following exception:

Traceback (most recent call last):
  File "/home/admin/.local/share/virtualenvs/Dev-jffJP19G/lib/python3.9/site-packages/nornir_scrapli/connection.py", line 98, in open
    connection = Scrapli(**parameters, platform=final_platform)
  File "/home/admin/.local/share/virtualenvs/Dev-jffJP19G/lib/python3.9/site-packages/scrapli/factory.py", line 507, in __new__
    final_driver, additional_kwargs = cls._get_driver(platform=platform, variant=variant)
  File "/home/admin/.local/share/virtualenvs/Dev-jffJP19G/lib/python3.9/site-packages/scrapli/factory.py", line 328, in _get_driver
    final_driver, additional_kwargs = cls._get_community_driver(
  File "/home/admin/.local/share/virtualenvs/Dev-jffJP19G/lib/python3.9/site-packages/scrapli/factory.py", line 290, in _get_community_driver
    platform_details = _get_community_platform_details(
  File "/home/admin/.local/share/virtualenvs/Dev-jffJP19G/lib/python3.9/site-packages/scrapli/factory.py", line 170, in _get_community_platform_details
    raise ScrapliModuleNotFound(warning) from exc
scrapli.exceptions.ScrapliModuleNotFound: 

******************************************************** Module not found! ********************************************************
Scrapli Community platform 'iosxe` not found!
To resolve this issue, ensure you have the correct platform name, and that a scrapli  community platform of that name exists!
***********************************************************************************************************************************


The above exception was the direct cause of the following exception:

Traceback (most recent call last):
  File "/home/admin/.local/share/virtualenvs/Dev-jffJP19G/lib/python3.9/site-packages/nornir/core/task.py", line 99, in start
    r = self.task(self, **self.params)
  File "/home/admin/.local/share/virtualenvs/Dev-jffJP19G/lib/python3.9/site-packages/nornir_scrapli/tasks/core/send_command.py", line 36, in send_command
    scrapli_conn = task.host.get_connection("scrapli", task.nornir.config)
  File "/home/admin/.local/share/virtualenvs/Dev-jffJP19G/lib/python3.9/site-packages/nornir/core/inventory.py", line 494, in get_connection
    self.open_connection(
  File "/home/admin/.local/share/virtualenvs/Dev-jffJP19G/lib/python3.9/site-packages/nornir/core/inventory.py", line 546, in open_connection
    conn_obj.open(
  File "/home/admin/.local/share/virtualenvs/Dev-jffJP19G/lib/python3.9/site-packages/nornir_scrapli/connection.py", line 100, in open
    raise NornirScrapliInvalidPlatform(
nornir_scrapli.exceptions.NornirScrapliInvalidPlatform: Provided platform `iosxe` is not a valid scrapli or napalm platform, or is not a valid scrapli-community platform.

2024-06-25 19:08:40,260 -  nornir.core -     INFO -        run() - Running task 'send_command' with args {'command': 'show ip int brief'} on 3 hosts
2024-06-25 19:08:40,560 - nornir.core.task -    ERROR -      start() - Host 'spine1': task 'send_command' failed with traceback:
Traceback (most recent call last):
  File "/home/admin/.local/share/virtualenvs/Dev-jffJP19G/lib/python3.9/site-packages/nornir/core/task.py", line 99, in start
    r = self.task(self, **self.params)
  File "/home/admin/.local/share/virtualenvs/Dev-jffJP19G/lib/python3.9/site-packages/nornir_scrapli/tasks/core/send_command.py", line 36, in send_command
    scrapli_conn = task.host.get_connection("scrapli", task.nornir.config)
  File "/home/admin/.local/share/virtualenvs/Dev-jffJP19G/lib/python3.9/site-packages/nornir/core/inventory.py", line 494, in get_connection
    self.open_connection(
  File "/home/admin/.local/share/virtualenvs/Dev-jffJP19G/lib/python3.9/site-packages/nornir/core/inventory.py", line 546, in open_connection
    conn_obj.open(
  File "/home/admin/.local/share/virtualenvs/Dev-jffJP19G/lib/python3.9/site-packages/nornir_scrapli/connection.py", line 105, in open
    connection.open()
  File "/home/admin/.local/share/virtualenvs/Dev-jffJP19G/lib/python3.9/site-packages/scrapli/driver/base/sync_driver.py", line 93, in open
    self.channel.channel_authenticate_ssh(
  File "/home/admin/.local/share/virtualenvs/Dev-jffJP19G/lib/python3.9/site-packages/scrapli/decorators.py", line 223, in decorate
    return _multiprocessing_timeout(
  File "/home/admin/.local/share/virtualenvs/Dev-jffJP19G/lib/python3.9/site-packages/scrapli/decorators.py", line 114, in _multiprocessing_timeout
    return future.result()
  File "/usr/lib64/python3.9/concurrent/futures/_base.py", line 439, in result
    return self.__get_result()
  File "/usr/lib64/python3.9/concurrent/futures/_base.py", line 391, in __get_result
    raise self._exception
  File "/usr/lib64/python3.9/concurrent/futures/thread.py", line 58, in run
    result = self.fn(*self.args, **self.kwargs)
  File "/home/admin/.local/share/virtualenvs/Dev-jffJP19G/lib/python3.9/site-packages/scrapli/channel/sync_channel.py", line 296, in channel_authenticate_ssh
    self._ssh_message_handler(output=authenticate_buf)
  File "/home/admin/.local/share/virtualenvs/Dev-jffJP19G/lib/python3.9/site-packages/scrapli/channel/base_channel.py", line 476, in _ssh_message_handler
    raise ScrapliAuthenticationFailed(msg)
scrapli.exceptions.ScrapliAuthenticationFailed: Host key verification failed

2024-06-25 19:09:05,215 -  nornir.core -     INFO -        run() - Running task 'send_command' with args {'command': 'show ip int brief'} on 3 hosts
2024-06-25 19:09:05,486 - nornir.core.task -    ERROR -      start() - Host 'spine1': task 'send_command' failed with traceback:
Traceback (most recent call last):
  File "/home/admin/.local/share/virtualenvs/Dev-jffJP19G/lib/python3.9/site-packages/nornir/core/task.py", line 99, in start
    r = self.task(self, **self.params)
  File "/home/admin/.local/share/virtualenvs/Dev-jffJP19G/lib/python3.9/site-packages/nornir_scrapli/tasks/core/send_command.py", line 36, in send_command
    scrapli_conn = task.host.get_connection("scrapli", task.nornir.config)
  File "/home/admin/.local/share/virtualenvs/Dev-jffJP19G/lib/python3.9/site-packages/nornir/core/inventory.py", line 494, in get_connection
    self.open_connection(
  File "/home/admin/.local/share/virtualenvs/Dev-jffJP19G/lib/python3.9/site-packages/nornir/core/inventory.py", line 546, in open_connection
    conn_obj.open(
  File "/home/admin/.local/share/virtualenvs/Dev-jffJP19G/lib/python3.9/site-packages/nornir_scrapli/connection.py", line 105, in open
    connection.open()
  File "/home/admin/.local/share/virtualenvs/Dev-jffJP19G/lib/python3.9/site-packages/scrapli/driver/base/sync_driver.py", line 93, in open
    self.channel.channel_authenticate_ssh(
  File "/home/admin/.local/share/virtualenvs/Dev-jffJP19G/lib/python3.9/site-packages/scrapli/decorators.py", line 223, in decorate
    return _multiprocessing_timeout(
  File "/home/admin/.local/share/virtualenvs/Dev-jffJP19G/lib/python3.9/site-packages/scrapli/decorators.py", line 114, in _multiprocessing_timeout
    return future.result()
  File "/usr/lib64/python3.9/concurrent/futures/_base.py", line 439, in result
    return self.__get_result()
  File "/usr/lib64/python3.9/concurrent/futures/_base.py", line 391, in __get_result
    raise self._exception
  File "/usr/lib64/python3.9/concurrent/futures/thread.py", line 58, in run
    result = self.fn(*self.args, **self.kwargs)
  File "/home/admin/.local/share/virtualenvs/Dev-jffJP19G/lib/python3.9/site-packages/scrapli/channel/sync_channel.py", line 296, in channel_authenticate_ssh
    self._ssh_message_handler(output=authenticate_buf)
  File "/home/admin/.local/share/virtualenvs/Dev-jffJP19G/lib/python3.9/site-packages/scrapli/channel/base_channel.py", line 476, in _ssh_message_handler
    raise ScrapliAuthenticationFailed(msg)
scrapli.exceptions.ScrapliAuthenticationFailed: Host key verification failed

2024-06-25 19:09:22,645 -  nornir.core -     INFO -        run() - Running task 'send_command' with args {'command': 'show ip int brief'} on 3 hosts
2024-06-25 19:09:29,152 - nornir.core.task -    ERROR -      start() - Host 'spine1': task 'send_command' failed with traceback:
Traceback (most recent call last):
  File "/home/admin/.local/share/virtualenvs/Dev-jffJP19G/lib/python3.9/site-packages/nornir/core/task.py", line 99, in start
    r = self.task(self, **self.params)
  File "/home/admin/.local/share/virtualenvs/Dev-jffJP19G/lib/python3.9/site-packages/nornir_scrapli/tasks/core/send_command.py", line 36, in send_command
    scrapli_conn = task.host.get_connection("scrapli", task.nornir.config)
  File "/home/admin/.local/share/virtualenvs/Dev-jffJP19G/lib/python3.9/site-packages/nornir/core/inventory.py", line 494, in get_connection
    self.open_connection(
  File "/home/admin/.local/share/virtualenvs/Dev-jffJP19G/lib/python3.9/site-packages/nornir/core/inventory.py", line 546, in open_connection
    conn_obj.open(
  File "/home/admin/.local/share/virtualenvs/Dev-jffJP19G/lib/python3.9/site-packages/nornir_scrapli/connection.py", line 105, in open
    connection.open()
  File "/home/admin/.local/share/virtualenvs/Dev-jffJP19G/lib/python3.9/site-packages/scrapli/driver/base/sync_driver.py", line 93, in open
    self.channel.channel_authenticate_ssh(
  File "/home/admin/.local/share/virtualenvs/Dev-jffJP19G/lib/python3.9/site-packages/scrapli/decorators.py", line 223, in decorate
    return _multiprocessing_timeout(
  File "/home/admin/.local/share/virtualenvs/Dev-jffJP19G/lib/python3.9/site-packages/scrapli/decorators.py", line 114, in _multiprocessing_timeout
    return future.result()
  File "/usr/lib64/python3.9/concurrent/futures/_base.py", line 439, in result
    return self.__get_result()
  File "/usr/lib64/python3.9/concurrent/futures/_base.py", line 391, in __get_result
    raise self._exception
  File "/usr/lib64/python3.9/concurrent/futures/thread.py", line 58, in run
    result = self.fn(*self.args, **self.kwargs)
  File "/home/admin/.local/share/virtualenvs/Dev-jffJP19G/lib/python3.9/site-packages/scrapli/channel/sync_channel.py", line 296, in channel_authenticate_ssh
    self._ssh_message_handler(output=authenticate_buf)
  File "/home/admin/.local/share/virtualenvs/Dev-jffJP19G/lib/python3.9/site-packages/scrapli/channel/base_channel.py", line 476, in _ssh_message_handler
    raise ScrapliAuthenticationFailed(msg)
scrapli.exceptions.ScrapliAuthenticationFailed: b"\npermission denied, please try again.\nadmin@192.168.1.102's password: "

2024-06-25 19:10:45,554 -  nornir.core -     INFO -        run() - Running task 'send_command' with args {'command': 'show ip int brief'} on 3 hosts
2024-06-25 19:10:52,055 - nornir.core.task -    ERROR -      start() - Host 'spine1': task 'send_command' failed with traceback:
Traceback (most recent call last):
  File "/home/admin/.local/share/virtualenvs/Dev-jffJP19G/lib/python3.9/site-packages/nornir/core/task.py", line 99, in start
    r = self.task(self, **self.params)
  File "/home/admin/.local/share/virtualenvs/Dev-jffJP19G/lib/python3.9/site-packages/nornir_scrapli/tasks/core/send_command.py", line 36, in send_command
    scrapli_conn = task.host.get_connection("scrapli", task.nornir.config)
  File "/home/admin/.local/share/virtualenvs/Dev-jffJP19G/lib/python3.9/site-packages/nornir/core/inventory.py", line 494, in get_connection
    self.open_connection(
  File "/home/admin/.local/share/virtualenvs/Dev-jffJP19G/lib/python3.9/site-packages/nornir/core/inventory.py", line 546, in open_connection
    conn_obj.open(
  File "/home/admin/.local/share/virtualenvs/Dev-jffJP19G/lib/python3.9/site-packages/nornir_scrapli/connection.py", line 105, in open
    connection.open()
  File "/home/admin/.local/share/virtualenvs/Dev-jffJP19G/lib/python3.9/site-packages/scrapli/driver/base/sync_driver.py", line 93, in open
    self.channel.channel_authenticate_ssh(
  File "/home/admin/.local/share/virtualenvs/Dev-jffJP19G/lib/python3.9/site-packages/scrapli/decorators.py", line 223, in decorate
    return _multiprocessing_timeout(
  File "/home/admin/.local/share/virtualenvs/Dev-jffJP19G/lib/python3.9/site-packages/scrapli/decorators.py", line 114, in _multiprocessing_timeout
    return future.result()
  File "/usr/lib64/python3.9/concurrent/futures/_base.py", line 439, in result
    return self.__get_result()
  File "/usr/lib64/python3.9/concurrent/futures/_base.py", line 391, in __get_result
    raise self._exception
  File "/usr/lib64/python3.9/concurrent/futures/thread.py", line 58, in run
    result = self.fn(*self.args, **self.kwargs)
  File "/home/admin/.local/share/virtualenvs/Dev-jffJP19G/lib/python3.9/site-packages/scrapli/channel/sync_channel.py", line 296, in channel_authenticate_ssh
    self._ssh_message_handler(output=authenticate_buf)
  File "/home/admin/.local/share/virtualenvs/Dev-jffJP19G/lib/python3.9/site-packages/scrapli/channel/base_channel.py", line 476, in _ssh_message_handler
    raise ScrapliAuthenticationFailed(msg)
scrapli.exceptions.ScrapliAuthenticationFailed: b"\npermission denied, please try again.\nadmin@192.168.1.102's password: "

2024-06-25 19:13:06,872 -  nornir.core -     INFO -        run() - Running task 'send_command' with args {'command': 'show ip int brief'} on 3 hosts
2024-06-25 19:13:13,368 - nornir.core.task -    ERROR -      start() - Host 'spine1': task 'send_command' failed with traceback:
Traceback (most recent call last):
  File "/home/admin/.local/share/virtualenvs/Dev-jffJP19G/lib/python3.9/site-packages/nornir/core/task.py", line 99, in start
    r = self.task(self, **self.params)
  File "/home/admin/.local/share/virtualenvs/Dev-jffJP19G/lib/python3.9/site-packages/nornir_scrapli/tasks/core/send_command.py", line 36, in send_command
    scrapli_conn = task.host.get_connection("scrapli", task.nornir.config)
  File "/home/admin/.local/share/virtualenvs/Dev-jffJP19G/lib/python3.9/site-packages/nornir/core/inventory.py", line 494, in get_connection
    self.open_connection(
  File "/home/admin/.local/share/virtualenvs/Dev-jffJP19G/lib/python3.9/site-packages/nornir/core/inventory.py", line 546, in open_connection
    conn_obj.open(
  File "/home/admin/.local/share/virtualenvs/Dev-jffJP19G/lib/python3.9/site-packages/nornir_scrapli/connection.py", line 105, in open
    connection.open()
  File "/home/admin/.local/share/virtualenvs/Dev-jffJP19G/lib/python3.9/site-packages/scrapli/driver/base/sync_driver.py", line 93, in open
    self.channel.channel_authenticate_ssh(
  File "/home/admin/.local/share/virtualenvs/Dev-jffJP19G/lib/python3.9/site-packages/scrapli/decorators.py", line 223, in decorate
    return _multiprocessing_timeout(
  File "/home/admin/.local/share/virtualenvs/Dev-jffJP19G/lib/python3.9/site-packages/scrapli/decorators.py", line 114, in _multiprocessing_timeout
    return future.result()
  File "/usr/lib64/python3.9/concurrent/futures/_base.py", line 439, in result
    return self.__get_result()
  File "/usr/lib64/python3.9/concurrent/futures/_base.py", line 391, in __get_result
    raise self._exception
  File "/usr/lib64/python3.9/concurrent/futures/thread.py", line 58, in run
    result = self.fn(*self.args, **self.kwargs)
  File "/home/admin/.local/share/virtualenvs/Dev-jffJP19G/lib/python3.9/site-packages/scrapli/channel/sync_channel.py", line 296, in channel_authenticate_ssh
    self._ssh_message_handler(output=authenticate_buf)
  File "/home/admin/.local/share/virtualenvs/Dev-jffJP19G/lib/python3.9/site-packages/scrapli/channel/base_channel.py", line 476, in _ssh_message_handler
    raise ScrapliAuthenticationFailed(msg)
scrapli.exceptions.ScrapliAuthenticationFailed: b"\npermission denied, please try again.\nadmin@192.168.1.102's password: "

2024-06-25 19:14:40,981 -  nornir.core -     INFO -        run() - Running task 'send_command' with args {'command': 'show ip int brief'} on 3 hosts
2024-06-25 20:28:40,967 -  nornir.core -     INFO -        run() - Running task 'send_command' with args {'command': 'show ip int brief'} on 3 hosts
2024-06-25 20:35:17,810 -  nornir.core -     INFO -        run() - Running task 'netconf_get_config' with args {'source': 'running'} on 3 hosts
2024-06-25 20:35:42,375 -  nornir.core -     INFO -        run() - Running task 'netconf_get_config' with args {'source': 'running'} on 3 hosts
2024-06-25 20:35:48,835 -  nornir.core -     INFO -        run() - Running task 'netconf_get_config' with args {'source': 'running'} on 3 hosts
2024-06-25 20:35:59,716 -  nornir.core -     INFO -        run() - Running task 'netconf_get_config' with args {'source': 'running'} on 3 hosts
2024-06-25 20:36:03,884 -  nornir.core -     INFO -        run() - Running task 'netconf_get_config' with args {'source': 'running'} on 3 hosts
2024-06-25 20:36:16,820 -  nornir.core -     INFO -        run() - Running task 'netconf_get_config' with args {'source': 'running'} on 3 hosts
2024-06-25 20:37:28,971 -  nornir.core -     INFO -        run() - Running task 'netconf_get' with args {'source': 'running'} on 3 hosts
2024-06-25 20:37:28,974 - nornir.core.task -    ERROR -      start() - Host 'leaf1': task 'netconf_get' failed with traceback:
Traceback (most recent call last):
  File "/home/admin/.local/share/virtualenvs/Dev-jffJP19G/lib/python3.9/site-packages/nornir/core/task.py", line 99, in start
    r = self.task(self, **self.params)
TypeError: netconf_get() got an unexpected keyword argument 'source'

2024-06-25 20:37:28,974 - nornir.core.task -    ERROR -      start() - Host 'leaf2': task 'netconf_get' failed with traceback:
Traceback (most recent call last):
  File "/home/admin/.local/share/virtualenvs/Dev-jffJP19G/lib/python3.9/site-packages/nornir/core/task.py", line 99, in start
    r = self.task(self, **self.params)
TypeError: netconf_get() got an unexpected keyword argument 'source'

2024-06-25 20:37:28,975 - nornir.core.task -    ERROR -      start() - Host 'spine1': task 'netconf_get' failed with traceback:
Traceback (most recent call last):
  File "/home/admin/.local/share/virtualenvs/Dev-jffJP19G/lib/python3.9/site-packages/nornir/core/task.py", line 99, in start
    r = self.task(self, **self.params)
TypeError: netconf_get() got an unexpected keyword argument 'source'

2024-06-25 20:39:31,830 -  nornir.core -     INFO -        run() - Running task 'netconf_get' with args {'filter_': '\n<interfaces xmlns="urn:ietf:params:xml:ns:yang:ietf-interfaces">\n    <interface>\n    <name>GigabitEthernet1</name>\n    </interface>\n</interfaces>\n', 'filter_type': 'subtree'} on 3 hosts
2024-06-25 20:40:55,230 -  nornir.core -     INFO -        run() - Running task 'netconf_get' with args {'filter_': '\n<interfaces xmlns="urn:ietf:params:xml:ns:yang:ietf-interfaces">\n    <interface>\n    <name>Ethernet1</name>\n    </interface>\n</interfaces>\n', 'filter_type': 'subtree'} on 3 hosts
2024-06-25 20:41:08,841 -  nornir.core -     INFO -        run() - Running task 'netconf_get' with args {'filter_': '\n<interfaces xmlns="urn:ietf:params:xml:ns:yang:ietf-interfaces">\n    <interface>\n    <name>Ethernet1</name>\n    </interface>\n</interfaces>\n', 'filter_type': 'subtree'} on 3 hosts
2024-06-25 20:41:20,310 -  nornir.core -     INFO -        run() - Running task 'netconf_get' with args {'filter_': '\n<interfaces xmlns="urn:ietf:params:xml:ns:yang:ietf-interfaces">\n    <interface>\n    <name>Ethernet1</name>\n    </interface>\n</interfaces>\n', 'filter_type': 'subtree'} on 3 hosts
2024-06-25 20:41:48,197 -  nornir.core -     INFO -        run() - Running task 'netconf_get' with args {'filter_': '\n<interfaces xmlns="urn:ietf:params:xml:ns:yang:ietf-interfaces">\n    <interface>\n    </interface>\n</interfaces>\n', 'filter_type': 'subtree'} on 3 hosts
2024-06-25 20:45:50,156 -  nornir.core -     INFO -        run() - Running task 'Get running config from each host' with args {'source': 'running'} on 3 hosts
2024-06-25 20:46:26,321 -  nornir.core -     INFO -        run() - Running task 'Get running config from each host' with args {'source': 'running'} on 3 hosts
2024-06-25 20:57:57,691 -  nornir.core -     INFO -        run() - Running task 'netconf_get' with args {'source': 'running'} on 3 hosts
2024-06-25 20:57:57,693 - nornir.core.task -    ERROR -      start() - Host 'leaf1': task 'netconf_get' failed with traceback:
Traceback (most recent call last):
  File "/home/admin/.local/share/virtualenvs/Dev-jffJP19G/lib/python3.9/site-packages/nornir/core/task.py", line 99, in start
    r = self.task(self, **self.params)
TypeError: netconf_get() got an unexpected keyword argument 'source'

2024-06-25 20:57:57,693 - nornir.core.task -    ERROR -      start() - Host 'leaf2': task 'netconf_get' failed with traceback:
Traceback (most recent call last):
  File "/home/admin/.local/share/virtualenvs/Dev-jffJP19G/lib/python3.9/site-packages/nornir/core/task.py", line 99, in start
    r = self.task(self, **self.params)
TypeError: netconf_get() got an unexpected keyword argument 'source'

2024-06-25 20:57:57,694 - nornir.core.task -    ERROR -      start() - Host 'spine1': task 'netconf_get' failed with traceback:
Traceback (most recent call last):
  File "/home/admin/.local/share/virtualenvs/Dev-jffJP19G/lib/python3.9/site-packages/nornir/core/task.py", line 99, in start
    r = self.task(self, **self.params)
TypeError: netconf_get() got an unexpected keyword argument 'source'

2024-06-25 20:58:42,816 -  nornir.core -     INFO -        run() - Running task 'netconf_get_config' with args {'source': 'running'} on 3 hosts
2024-06-25 20:59:16,863 -  nornir.core -     INFO -        run() - Running task 'netconf_get_config' with args {'source': 'running'} on 3 hosts
2024-06-25 20:59:53,577 -  nornir.core -     INFO -        run() - Running task 'netconf_get_config' with args {'source': 'running'} on 3 hosts
2024-06-25 21:02:28,736 -  nornir.core -     INFO -        run() - Running task 'get_netconf_config' with args {} on 3 hosts
2024-06-25 21:22:09,132 -  nornir.core -     INFO -        run() - Running task 'get_netconf_config' with args {} on 1 hosts
2024-06-25 21:25:18,814 -  nornir.core -     INFO -        run() - Running task 'get_netconf_config' with args {} on 1 hosts
2024-06-25 21:25:38,749 -  nornir.core -     INFO -        run() - Running task 'get_netconf_config' with args {} on 1 hosts
2024-06-25 21:40:46,558 -  nornir.core -     INFO -        run() - Running task 'get_netconf_config' with args {} on 1 hosts
2024-06-25 21:40:51,978 -  nornir.core -     INFO -        run() - Running task 'get_netconf_config' with args {} on 1 hosts
2024-06-25 21:44:01,024 -  nornir.core -     INFO -        run() - Running task 'get_running_config' with args {} on 1 hosts
2024-06-25 21:48:31,619 -  nornir.core -     INFO -        run() - Running task 'get_running_config' with args {} on 1 hosts
2024-06-25 21:53:41,023 -  nornir.core -     INFO -        run() - Running task 'get_running_config' with args {} on 1 hosts
2024-06-25 21:53:46,940 -  nornir.core -     INFO -        run() - Running task 'get_running_config' with args {} on 1 hosts
2024-06-25 21:53:49,494 -  nornir.core -     INFO -        run() - Running task 'get_running_config' with args {} on 1 hosts
2024-06-25 21:54:36,479 -  nornir.core -     INFO -        run() - Running task 'get_running_config' with args {} on 1 hosts
2024-06-26 10:17:42,763 -  nornir.core -     INFO -        run() - Running task 'netconf_get_config' with args {} on 6 hosts
2024-06-26 10:17:42,782 - nornir.core.task -    ERROR -      start() - Host 'leaf3': task 'netconf_get_config' failed with traceback:
Traceback (most recent call last):
  File "/home/admin/.local/share/virtualenvs/Dev-jffJP19G/lib/python3.9/site-packages/nornir/core/task.py", line 99, in start
    r = self.task(self, **self.params)
  File "/home/admin/Dev/arista_vxlan_project/python_scripts/vlan_oper.py", line 11, in netconf_get_config
    with manager.connect(
  File "/home/admin/.local/share/virtualenvs/Dev-jffJP19G/lib/python3.9/site-packages/ncclient/manager.py", line 187, in connect
    return connect_ssh(*args, **kwds)
  File "/home/admin/.local/share/virtualenvs/Dev-jffJP19G/lib/python3.9/site-packages/ncclient/manager.py", line 139, in connect_ssh
    session.connect(*args, **kwds)
  File "/home/admin/.local/share/virtualenvs/Dev-jffJP19G/lib/python3.9/site-packages/ncclient/transport/ssh.py", line 288, in connect
    raise SSHError("Could not open socket to %s:%s" % (host, port))
ncclient.transport.errors.SSHError: Could not open socket to 192.168.1.103:830

2024-06-26 10:17:42,783 - nornir.core.task -    ERROR -      start() - Host 'leaf2': task 'netconf_get_config' failed with traceback:
Traceback (most recent call last):
  File "/home/admin/.local/share/virtualenvs/Dev-jffJP19G/lib/python3.9/site-packages/nornir/core/task.py", line 99, in start
    r = self.task(self, **self.params)
  File "/home/admin/Dev/arista_vxlan_project/python_scripts/vlan_oper.py", line 11, in netconf_get_config
    with manager.connect(
  File "/home/admin/.local/share/virtualenvs/Dev-jffJP19G/lib/python3.9/site-packages/ncclient/manager.py", line 187, in connect
    return connect_ssh(*args, **kwds)
  File "/home/admin/.local/share/virtualenvs/Dev-jffJP19G/lib/python3.9/site-packages/ncclient/manager.py", line 139, in connect_ssh
    session.connect(*args, **kwds)
  File "/home/admin/.local/share/virtualenvs/Dev-jffJP19G/lib/python3.9/site-packages/ncclient/transport/ssh.py", line 288, in connect
    raise SSHError("Could not open socket to %s:%s" % (host, port))
ncclient.transport.errors.SSHError: Could not open socket to 192.168.1.103:830

2024-06-26 10:17:42,784 - nornir.core.task -    ERROR -      start() - Host 'leaf1': task 'netconf_get_config' failed with traceback:
Traceback (most recent call last):
  File "/home/admin/.local/share/virtualenvs/Dev-jffJP19G/lib/python3.9/site-packages/nornir/core/task.py", line 99, in start
    r = self.task(self, **self.params)
  File "/home/admin/Dev/arista_vxlan_project/python_scripts/vlan_oper.py", line 11, in netconf_get_config
    with manager.connect(
  File "/home/admin/.local/share/virtualenvs/Dev-jffJP19G/lib/python3.9/site-packages/ncclient/manager.py", line 187, in connect
    return connect_ssh(*args, **kwds)
  File "/home/admin/.local/share/virtualenvs/Dev-jffJP19G/lib/python3.9/site-packages/ncclient/manager.py", line 139, in connect_ssh
    session.connect(*args, **kwds)
  File "/home/admin/.local/share/virtualenvs/Dev-jffJP19G/lib/python3.9/site-packages/ncclient/transport/ssh.py", line 288, in connect
    raise SSHError("Could not open socket to %s:%s" % (host, port))
ncclient.transport.errors.SSHError: Could not open socket to 192.168.1.102:830

2024-06-26 10:17:42,784 - nornir.core.task -    ERROR -      start() - Host 'spine2': task 'netconf_get_config' failed with traceback:
Traceback (most recent call last):
  File "/home/admin/.local/share/virtualenvs/Dev-jffJP19G/lib/python3.9/site-packages/nornir/core/task.py", line 99, in start
    r = self.task(self, **self.params)
  File "/home/admin/Dev/arista_vxlan_project/python_scripts/vlan_oper.py", line 11, in netconf_get_config
    with manager.connect(
  File "/home/admin/.local/share/virtualenvs/Dev-jffJP19G/lib/python3.9/site-packages/ncclient/manager.py", line 187, in connect
    return connect_ssh(*args, **kwds)
  File "/home/admin/.local/share/virtualenvs/Dev-jffJP19G/lib/python3.9/site-packages/ncclient/manager.py", line 139, in connect_ssh
    session.connect(*args, **kwds)
  File "/home/admin/.local/share/virtualenvs/Dev-jffJP19G/lib/python3.9/site-packages/ncclient/transport/ssh.py", line 288, in connect
    raise SSHError("Could not open socket to %s:%s" % (host, port))
ncclient.transport.errors.SSHError: Could not open socket to 192.168.1.101:830

2024-06-26 10:17:42,785 - nornir.core.task -    ERROR -      start() - Host 'leaf4': task 'netconf_get_config' failed with traceback:
Traceback (most recent call last):
  File "/home/admin/.local/share/virtualenvs/Dev-jffJP19G/lib/python3.9/site-packages/nornir/core/task.py", line 99, in start
    r = self.task(self, **self.params)
  File "/home/admin/Dev/arista_vxlan_project/python_scripts/vlan_oper.py", line 11, in netconf_get_config
    with manager.connect(
  File "/home/admin/.local/share/virtualenvs/Dev-jffJP19G/lib/python3.9/site-packages/ncclient/manager.py", line 187, in connect
    return connect_ssh(*args, **kwds)
  File "/home/admin/.local/share/virtualenvs/Dev-jffJP19G/lib/python3.9/site-packages/ncclient/manager.py", line 139, in connect_ssh
    session.connect(*args, **kwds)
  File "/home/admin/.local/share/virtualenvs/Dev-jffJP19G/lib/python3.9/site-packages/ncclient/transport/ssh.py", line 288, in connect
    raise SSHError("Could not open socket to %s:%s" % (host, port))
ncclient.transport.errors.SSHError: Could not open socket to 192.168.1.104:830

2024-06-26 10:17:42,785 - nornir.core.task -    ERROR -      start() - Host 'spine1': task 'netconf_get_config' failed with traceback:
Traceback (most recent call last):
  File "/home/admin/.local/share/virtualenvs/Dev-jffJP19G/lib/python3.9/site-packages/nornir/core/task.py", line 99, in start
    r = self.task(self, **self.params)
  File "/home/admin/Dev/arista_vxlan_project/python_scripts/vlan_oper.py", line 11, in netconf_get_config
    with manager.connect(
  File "/home/admin/.local/share/virtualenvs/Dev-jffJP19G/lib/python3.9/site-packages/ncclient/manager.py", line 187, in connect
    return connect_ssh(*args, **kwds)
  File "/home/admin/.local/share/virtualenvs/Dev-jffJP19G/lib/python3.9/site-packages/ncclient/manager.py", line 139, in connect_ssh
    session.connect(*args, **kwds)
  File "/home/admin/.local/share/virtualenvs/Dev-jffJP19G/lib/python3.9/site-packages/ncclient/transport/ssh.py", line 288, in connect
    raise SSHError("Could not open socket to %s:%s" % (host, port))
ncclient.transport.errors.SSHError: Could not open socket to 192.168.1.100:830

2024-06-26 10:19:15,342 -  nornir.core -     INFO -        run() - Running task 'netconf_get_config' with args {} on 6 hosts
2024-06-26 10:19:15,355 - nornir.core.task -    ERROR -      start() - Host 'spine2': task 'netconf_get_config' failed with traceback:
Traceback (most recent call last):
  File "/home/admin/.local/share/virtualenvs/Dev-jffJP19G/lib/python3.9/site-packages/nornir/core/task.py", line 99, in start
    r = self.task(self, **self.params)
  File "/home/admin/Dev/arista_vxlan_project/python_scripts/vlan_oper.py", line 11, in netconf_get_config
    with manager.connect(
  File "/home/admin/.local/share/virtualenvs/Dev-jffJP19G/lib/python3.9/site-packages/ncclient/manager.py", line 187, in connect
    return connect_ssh(*args, **kwds)
  File "/home/admin/.local/share/virtualenvs/Dev-jffJP19G/lib/python3.9/site-packages/ncclient/manager.py", line 139, in connect_ssh
    session.connect(*args, **kwds)
  File "/home/admin/.local/share/virtualenvs/Dev-jffJP19G/lib/python3.9/site-packages/ncclient/transport/ssh.py", line 288, in connect
    raise SSHError("Could not open socket to %s:%s" % (host, port))
ncclient.transport.errors.SSHError: Could not open socket to 192.168.1.101:830

2024-06-26 10:19:15,356 - nornir.core.task -    ERROR -      start() - Host 'leaf2': task 'netconf_get_config' failed with traceback:
Traceback (most recent call last):
  File "/home/admin/.local/share/virtualenvs/Dev-jffJP19G/lib/python3.9/site-packages/nornir/core/task.py", line 99, in start
    r = self.task(self, **self.params)
  File "/home/admin/Dev/arista_vxlan_project/python_scripts/vlan_oper.py", line 11, in netconf_get_config
    with manager.connect(
  File "/home/admin/.local/share/virtualenvs/Dev-jffJP19G/lib/python3.9/site-packages/ncclient/manager.py", line 187, in connect
    return connect_ssh(*args, **kwds)
  File "/home/admin/.local/share/virtualenvs/Dev-jffJP19G/lib/python3.9/site-packages/ncclient/manager.py", line 139, in connect_ssh
    session.connect(*args, **kwds)
  File "/home/admin/.local/share/virtualenvs/Dev-jffJP19G/lib/python3.9/site-packages/ncclient/transport/ssh.py", line 288, in connect
    raise SSHError("Could not open socket to %s:%s" % (host, port))
ncclient.transport.errors.SSHError: Could not open socket to 192.168.1.103:830

2024-06-26 10:19:15,357 - nornir.core.task -    ERROR -      start() - Host 'spine1': task 'netconf_get_config' failed with traceback:
Traceback (most recent call last):
  File "/home/admin/.local/share/virtualenvs/Dev-jffJP19G/lib/python3.9/site-packages/nornir/core/task.py", line 99, in start
    r = self.task(self, **self.params)
  File "/home/admin/Dev/arista_vxlan_project/python_scripts/vlan_oper.py", line 11, in netconf_get_config
    with manager.connect(
  File "/home/admin/.local/share/virtualenvs/Dev-jffJP19G/lib/python3.9/site-packages/ncclient/manager.py", line 187, in connect
    return connect_ssh(*args, **kwds)
  File "/home/admin/.local/share/virtualenvs/Dev-jffJP19G/lib/python3.9/site-packages/ncclient/manager.py", line 139, in connect_ssh
    session.connect(*args, **kwds)
  File "/home/admin/.local/share/virtualenvs/Dev-jffJP19G/lib/python3.9/site-packages/ncclient/transport/ssh.py", line 288, in connect
    raise SSHError("Could not open socket to %s:%s" % (host, port))
ncclient.transport.errors.SSHError: Could not open socket to 192.168.1.100:830

2024-06-26 10:19:15,358 - nornir.core.task -    ERROR -      start() - Host 'leaf1': task 'netconf_get_config' failed with traceback:
Traceback (most recent call last):
  File "/home/admin/.local/share/virtualenvs/Dev-jffJP19G/lib/python3.9/site-packages/nornir/core/task.py", line 99, in start
    r = self.task(self, **self.params)
  File "/home/admin/Dev/arista_vxlan_project/python_scripts/vlan_oper.py", line 11, in netconf_get_config
    with manager.connect(
  File "/home/admin/.local/share/virtualenvs/Dev-jffJP19G/lib/python3.9/site-packages/ncclient/manager.py", line 187, in connect
    return connect_ssh(*args, **kwds)
  File "/home/admin/.local/share/virtualenvs/Dev-jffJP19G/lib/python3.9/site-packages/ncclient/manager.py", line 139, in connect_ssh
    session.connect(*args, **kwds)
  File "/home/admin/.local/share/virtualenvs/Dev-jffJP19G/lib/python3.9/site-packages/ncclient/transport/ssh.py", line 288, in connect
    raise SSHError("Could not open socket to %s:%s" % (host, port))
ncclient.transport.errors.SSHError: Could not open socket to 192.168.1.102:830

2024-06-26 10:19:15,360 - nornir.core.task -    ERROR -      start() - Host 'leaf4': task 'netconf_get_config' failed with traceback:
Traceback (most recent call last):
  File "/home/admin/.local/share/virtualenvs/Dev-jffJP19G/lib/python3.9/site-packages/nornir/core/task.py", line 99, in start
    r = self.task(self, **self.params)
  File "/home/admin/Dev/arista_vxlan_project/python_scripts/vlan_oper.py", line 11, in netconf_get_config
    with manager.connect(
  File "/home/admin/.local/share/virtualenvs/Dev-jffJP19G/lib/python3.9/site-packages/ncclient/manager.py", line 187, in connect
    return connect_ssh(*args, **kwds)
  File "/home/admin/.local/share/virtualenvs/Dev-jffJP19G/lib/python3.9/site-packages/ncclient/manager.py", line 139, in connect_ssh
    session.connect(*args, **kwds)
  File "/home/admin/.local/share/virtualenvs/Dev-jffJP19G/lib/python3.9/site-packages/ncclient/transport/ssh.py", line 288, in connect
    raise SSHError("Could not open socket to %s:%s" % (host, port))
ncclient.transport.errors.SSHError: Could not open socket to 192.168.1.104:830

2024-06-26 10:19:15,360 - nornir.core.task -    ERROR -      start() - Host 'leaf3': task 'netconf_get_config' failed with traceback:
Traceback (most recent call last):
  File "/home/admin/.local/share/virtualenvs/Dev-jffJP19G/lib/python3.9/site-packages/nornir/core/task.py", line 99, in start
    r = self.task(self, **self.params)
  File "/home/admin/Dev/arista_vxlan_project/python_scripts/vlan_oper.py", line 11, in netconf_get_config
    with manager.connect(
  File "/home/admin/.local/share/virtualenvs/Dev-jffJP19G/lib/python3.9/site-packages/ncclient/manager.py", line 187, in connect
    return connect_ssh(*args, **kwds)
  File "/home/admin/.local/share/virtualenvs/Dev-jffJP19G/lib/python3.9/site-packages/ncclient/manager.py", line 139, in connect_ssh
    session.connect(*args, **kwds)
  File "/home/admin/.local/share/virtualenvs/Dev-jffJP19G/lib/python3.9/site-packages/ncclient/transport/ssh.py", line 288, in connect
    raise SSHError("Could not open socket to %s:%s" % (host, port))
ncclient.transport.errors.SSHError: Could not open socket to 192.168.1.103:830

2024-06-26 10:23:27,613 -  nornir.core -     INFO -        run() - Running task 'netconf_get_config' with args {} on 6 hosts
2024-06-26 10:23:27,627 - nornir.core.task -    ERROR -      start() - Host 'spine1': task 'netconf_get_config' failed with traceback:
Traceback (most recent call last):
  File "/home/admin/.local/share/virtualenvs/Dev-jffJP19G/lib/python3.9/site-packages/nornir/core/task.py", line 99, in start
    r = self.task(self, **self.params)
  File "/home/admin/Dev/arista_vxlan_project/python_scripts/vlan_oper.py", line 11, in netconf_get_config
    with manager.connect(
  File "/home/admin/.local/share/virtualenvs/Dev-jffJP19G/lib/python3.9/site-packages/ncclient/manager.py", line 187, in connect
    return connect_ssh(*args, **kwds)
  File "/home/admin/.local/share/virtualenvs/Dev-jffJP19G/lib/python3.9/site-packages/ncclient/manager.py", line 139, in connect_ssh
    session.connect(*args, **kwds)
  File "/home/admin/.local/share/virtualenvs/Dev-jffJP19G/lib/python3.9/site-packages/ncclient/transport/ssh.py", line 288, in connect
    raise SSHError("Could not open socket to %s:%s" % (host, port))
ncclient.transport.errors.SSHError: Could not open socket to 192.168.1.100:830

2024-06-26 10:23:27,632 - nornir.core.task -    ERROR -      start() - Host 'spine2': task 'netconf_get_config' failed with traceback:
Traceback (most recent call last):
  File "/home/admin/.local/share/virtualenvs/Dev-jffJP19G/lib/python3.9/site-packages/nornir/core/task.py", line 99, in start
    r = self.task(self, **self.params)
  File "/home/admin/Dev/arista_vxlan_project/python_scripts/vlan_oper.py", line 11, in netconf_get_config
    with manager.connect(
  File "/home/admin/.local/share/virtualenvs/Dev-jffJP19G/lib/python3.9/site-packages/ncclient/manager.py", line 187, in connect
    return connect_ssh(*args, **kwds)
  File "/home/admin/.local/share/virtualenvs/Dev-jffJP19G/lib/python3.9/site-packages/ncclient/manager.py", line 139, in connect_ssh
    session.connect(*args, **kwds)
  File "/home/admin/.local/share/virtualenvs/Dev-jffJP19G/lib/python3.9/site-packages/ncclient/transport/ssh.py", line 288, in connect
    raise SSHError("Could not open socket to %s:%s" % (host, port))
ncclient.transport.errors.SSHError: Could not open socket to 192.168.1.101:830

2024-06-26 10:23:27,634 - nornir.core.task -    ERROR -      start() - Host 'leaf1': task 'netconf_get_config' failed with traceback:
Traceback (most recent call last):
  File "/home/admin/.local/share/virtualenvs/Dev-jffJP19G/lib/python3.9/site-packages/nornir/core/task.py", line 99, in start
    r = self.task(self, **self.params)
  File "/home/admin/Dev/arista_vxlan_project/python_scripts/vlan_oper.py", line 11, in netconf_get_config
    with manager.connect(
  File "/home/admin/.local/share/virtualenvs/Dev-jffJP19G/lib/python3.9/site-packages/ncclient/manager.py", line 187, in connect
    return connect_ssh(*args, **kwds)
  File "/home/admin/.local/share/virtualenvs/Dev-jffJP19G/lib/python3.9/site-packages/ncclient/manager.py", line 139, in connect_ssh
    session.connect(*args, **kwds)
  File "/home/admin/.local/share/virtualenvs/Dev-jffJP19G/lib/python3.9/site-packages/ncclient/transport/ssh.py", line 288, in connect
    raise SSHError("Could not open socket to %s:%s" % (host, port))
ncclient.transport.errors.SSHError: Could not open socket to 192.168.1.102:830

2024-06-26 10:23:27,638 - nornir.core.task -    ERROR -      start() - Host 'leaf2': task 'netconf_get_config' failed with traceback:
Traceback (most recent call last):
  File "/home/admin/.local/share/virtualenvs/Dev-jffJP19G/lib/python3.9/site-packages/nornir/core/task.py", line 99, in start
    r = self.task(self, **self.params)
  File "/home/admin/Dev/arista_vxlan_project/python_scripts/vlan_oper.py", line 11, in netconf_get_config
    with manager.connect(
  File "/home/admin/.local/share/virtualenvs/Dev-jffJP19G/lib/python3.9/site-packages/ncclient/manager.py", line 187, in connect
    return connect_ssh(*args, **kwds)
  File "/home/admin/.local/share/virtualenvs/Dev-jffJP19G/lib/python3.9/site-packages/ncclient/manager.py", line 139, in connect_ssh
    session.connect(*args, **kwds)
  File "/home/admin/.local/share/virtualenvs/Dev-jffJP19G/lib/python3.9/site-packages/ncclient/transport/ssh.py", line 288, in connect
    raise SSHError("Could not open socket to %s:%s" % (host, port))
ncclient.transport.errors.SSHError: Could not open socket to 192.168.1.103:830

2024-06-26 10:23:27,638 - nornir.core.task -    ERROR -      start() - Host 'leaf3': task 'netconf_get_config' failed with traceback:
Traceback (most recent call last):
  File "/home/admin/.local/share/virtualenvs/Dev-jffJP19G/lib/python3.9/site-packages/nornir/core/task.py", line 99, in start
    r = self.task(self, **self.params)
  File "/home/admin/Dev/arista_vxlan_project/python_scripts/vlan_oper.py", line 11, in netconf_get_config
    with manager.connect(
  File "/home/admin/.local/share/virtualenvs/Dev-jffJP19G/lib/python3.9/site-packages/ncclient/manager.py", line 187, in connect
    return connect_ssh(*args, **kwds)
  File "/home/admin/.local/share/virtualenvs/Dev-jffJP19G/lib/python3.9/site-packages/ncclient/manager.py", line 139, in connect_ssh
    session.connect(*args, **kwds)
  File "/home/admin/.local/share/virtualenvs/Dev-jffJP19G/lib/python3.9/site-packages/ncclient/transport/ssh.py", line 288, in connect
    raise SSHError("Could not open socket to %s:%s" % (host, port))
ncclient.transport.errors.SSHError: Could not open socket to 192.168.1.103:830

2024-06-26 10:23:27,639 - nornir.core.task -    ERROR -      start() - Host 'leaf4': task 'netconf_get_config' failed with traceback:
Traceback (most recent call last):
  File "/home/admin/.local/share/virtualenvs/Dev-jffJP19G/lib/python3.9/site-packages/nornir/core/task.py", line 99, in start
    r = self.task(self, **self.params)
  File "/home/admin/Dev/arista_vxlan_project/python_scripts/vlan_oper.py", line 11, in netconf_get_config
    with manager.connect(
  File "/home/admin/.local/share/virtualenvs/Dev-jffJP19G/lib/python3.9/site-packages/ncclient/manager.py", line 187, in connect
    return connect_ssh(*args, **kwds)
  File "/home/admin/.local/share/virtualenvs/Dev-jffJP19G/lib/python3.9/site-packages/ncclient/manager.py", line 139, in connect_ssh
    session.connect(*args, **kwds)
  File "/home/admin/.local/share/virtualenvs/Dev-jffJP19G/lib/python3.9/site-packages/ncclient/transport/ssh.py", line 288, in connect
    raise SSHError("Could not open socket to %s:%s" % (host, port))
ncclient.transport.errors.SSHError: Could not open socket to 192.168.1.104:830

2024-06-26 10:23:32,303 -  nornir.core -     INFO -        run() - Running task 'netconf_get_config' with args {} on 6 hosts
2024-06-26 10:23:32,317 - nornir.core.task -    ERROR -      start() - Host 'spine2': task 'netconf_get_config' failed with traceback:
Traceback (most recent call last):
  File "/home/admin/.local/share/virtualenvs/Dev-jffJP19G/lib/python3.9/site-packages/nornir/core/task.py", line 99, in start
    r = self.task(self, **self.params)
  File "/home/admin/Dev/arista_vxlan_project/python_scripts/vlan_oper.py", line 11, in netconf_get_config
    with manager.connect(
  File "/home/admin/.local/share/virtualenvs/Dev-jffJP19G/lib/python3.9/site-packages/ncclient/manager.py", line 187, in connect
    return connect_ssh(*args, **kwds)
  File "/home/admin/.local/share/virtualenvs/Dev-jffJP19G/lib/python3.9/site-packages/ncclient/manager.py", line 139, in connect_ssh
    session.connect(*args, **kwds)
  File "/home/admin/.local/share/virtualenvs/Dev-jffJP19G/lib/python3.9/site-packages/ncclient/transport/ssh.py", line 288, in connect
    raise SSHError("Could not open socket to %s:%s" % (host, port))
ncclient.transport.errors.SSHError: Could not open socket to 192.168.1.101:830

2024-06-26 10:23:32,318 - nornir.core.task -    ERROR -      start() - Host 'spine1': task 'netconf_get_config' failed with traceback:
Traceback (most recent call last):
  File "/home/admin/.local/share/virtualenvs/Dev-jffJP19G/lib/python3.9/site-packages/nornir/core/task.py", line 99, in start
    r = self.task(self, **self.params)
  File "/home/admin/Dev/arista_vxlan_project/python_scripts/vlan_oper.py", line 11, in netconf_get_config
    with manager.connect(
  File "/home/admin/.local/share/virtualenvs/Dev-jffJP19G/lib/python3.9/site-packages/ncclient/manager.py", line 187, in connect
    return connect_ssh(*args, **kwds)
  File "/home/admin/.local/share/virtualenvs/Dev-jffJP19G/lib/python3.9/site-packages/ncclient/manager.py", line 139, in connect_ssh
    session.connect(*args, **kwds)
  File "/home/admin/.local/share/virtualenvs/Dev-jffJP19G/lib/python3.9/site-packages/ncclient/transport/ssh.py", line 288, in connect
    raise SSHError("Could not open socket to %s:%s" % (host, port))
ncclient.transport.errors.SSHError: Could not open socket to 192.168.1.100:830

2024-06-26 10:23:32,319 - nornir.core.task -    ERROR -      start() - Host 'leaf1': task 'netconf_get_config' failed with traceback:
Traceback (most recent call last):
  File "/home/admin/.local/share/virtualenvs/Dev-jffJP19G/lib/python3.9/site-packages/nornir/core/task.py", line 99, in start
    r = self.task(self, **self.params)
  File "/home/admin/Dev/arista_vxlan_project/python_scripts/vlan_oper.py", line 11, in netconf_get_config
    with manager.connect(
  File "/home/admin/.local/share/virtualenvs/Dev-jffJP19G/lib/python3.9/site-packages/ncclient/manager.py", line 187, in connect
    return connect_ssh(*args, **kwds)
  File "/home/admin/.local/share/virtualenvs/Dev-jffJP19G/lib/python3.9/site-packages/ncclient/manager.py", line 139, in connect_ssh
    session.connect(*args, **kwds)
  File "/home/admin/.local/share/virtualenvs/Dev-jffJP19G/lib/python3.9/site-packages/ncclient/transport/ssh.py", line 288, in connect
    raise SSHError("Could not open socket to %s:%s" % (host, port))
ncclient.transport.errors.SSHError: Could not open socket to 192.168.1.102:830

2024-06-26 10:23:32,323 - nornir.core.task -    ERROR -      start() - Host 'leaf3': task 'netconf_get_config' failed with traceback:
Traceback (most recent call last):
  File "/home/admin/.local/share/virtualenvs/Dev-jffJP19G/lib/python3.9/site-packages/nornir/core/task.py", line 99, in start
    r = self.task(self, **self.params)
  File "/home/admin/Dev/arista_vxlan_project/python_scripts/vlan_oper.py", line 11, in netconf_get_config
    with manager.connect(
  File "/home/admin/.local/share/virtualenvs/Dev-jffJP19G/lib/python3.9/site-packages/ncclient/manager.py", line 187, in connect
    return connect_ssh(*args, **kwds)
  File "/home/admin/.local/share/virtualenvs/Dev-jffJP19G/lib/python3.9/site-packages/ncclient/manager.py", line 139, in connect_ssh
    session.connect(*args, **kwds)
  File "/home/admin/.local/share/virtualenvs/Dev-jffJP19G/lib/python3.9/site-packages/ncclient/transport/ssh.py", line 288, in connect
    raise SSHError("Could not open socket to %s:%s" % (host, port))
ncclient.transport.errors.SSHError: Could not open socket to 192.168.1.103:830

2024-06-26 10:23:32,324 - nornir.core.task -    ERROR -      start() - Host 'leaf2': task 'netconf_get_config' failed with traceback:
Traceback (most recent call last):
  File "/home/admin/.local/share/virtualenvs/Dev-jffJP19G/lib/python3.9/site-packages/nornir/core/task.py", line 99, in start
    r = self.task(self, **self.params)
  File "/home/admin/Dev/arista_vxlan_project/python_scripts/vlan_oper.py", line 11, in netconf_get_config
    with manager.connect(
  File "/home/admin/.local/share/virtualenvs/Dev-jffJP19G/lib/python3.9/site-packages/ncclient/manager.py", line 187, in connect
    return connect_ssh(*args, **kwds)
  File "/home/admin/.local/share/virtualenvs/Dev-jffJP19G/lib/python3.9/site-packages/ncclient/manager.py", line 139, in connect_ssh
    session.connect(*args, **kwds)
  File "/home/admin/.local/share/virtualenvs/Dev-jffJP19G/lib/python3.9/site-packages/ncclient/transport/ssh.py", line 288, in connect
    raise SSHError("Could not open socket to %s:%s" % (host, port))
ncclient.transport.errors.SSHError: Could not open socket to 192.168.1.103:830

2024-06-26 10:23:32,325 - nornir.core.task -    ERROR -      start() - Host 'leaf4': task 'netconf_get_config' failed with traceback:
Traceback (most recent call last):
  File "/home/admin/.local/share/virtualenvs/Dev-jffJP19G/lib/python3.9/site-packages/nornir/core/task.py", line 99, in start
    r = self.task(self, **self.params)
  File "/home/admin/Dev/arista_vxlan_project/python_scripts/vlan_oper.py", line 11, in netconf_get_config
    with manager.connect(
  File "/home/admin/.local/share/virtualenvs/Dev-jffJP19G/lib/python3.9/site-packages/ncclient/manager.py", line 187, in connect
    return connect_ssh(*args, **kwds)
  File "/home/admin/.local/share/virtualenvs/Dev-jffJP19G/lib/python3.9/site-packages/ncclient/manager.py", line 139, in connect_ssh
    session.connect(*args, **kwds)
  File "/home/admin/.local/share/virtualenvs/Dev-jffJP19G/lib/python3.9/site-packages/ncclient/transport/ssh.py", line 288, in connect
    raise SSHError("Could not open socket to %s:%s" % (host, port))
ncclient.transport.errors.SSHError: Could not open socket to 192.168.1.104:830

2024-06-26 10:25:06,042 -  nornir.core -     INFO -        run() - Running task 'netconf_get_config' with args {} on 6 hosts
2024-06-26 10:25:06,053 - nornir.core.task -    ERROR -      start() - Host 'spine1': task 'netconf_get_config' failed with traceback:
Traceback (most recent call last):
  File "/home/admin/.local/share/virtualenvs/Dev-jffJP19G/lib/python3.9/site-packages/nornir/core/task.py", line 99, in start
    r = self.task(self, **self.params)
  File "/home/admin/Dev/arista_vxlan_project/python_scripts/vlan_oper.py", line 11, in netconf_get_config
    with manager.connect(
  File "/home/admin/.local/share/virtualenvs/Dev-jffJP19G/lib/python3.9/site-packages/ncclient/manager.py", line 187, in connect
    return connect_ssh(*args, **kwds)
  File "/home/admin/.local/share/virtualenvs/Dev-jffJP19G/lib/python3.9/site-packages/ncclient/manager.py", line 139, in connect_ssh
    session.connect(*args, **kwds)
  File "/home/admin/.local/share/virtualenvs/Dev-jffJP19G/lib/python3.9/site-packages/ncclient/transport/ssh.py", line 288, in connect
    raise SSHError("Could not open socket to %s:%s" % (host, port))
ncclient.transport.errors.SSHError: Could not open socket to 192.168.1.100:830

2024-06-26 10:25:06,055 - nornir.core.task -    ERROR -      start() - Host 'spine2': task 'netconf_get_config' failed with traceback:
Traceback (most recent call last):
  File "/home/admin/.local/share/virtualenvs/Dev-jffJP19G/lib/python3.9/site-packages/nornir/core/task.py", line 99, in start
    r = self.task(self, **self.params)
  File "/home/admin/Dev/arista_vxlan_project/python_scripts/vlan_oper.py", line 11, in netconf_get_config
    with manager.connect(
  File "/home/admin/.local/share/virtualenvs/Dev-jffJP19G/lib/python3.9/site-packages/ncclient/manager.py", line 187, in connect
    return connect_ssh(*args, **kwds)
  File "/home/admin/.local/share/virtualenvs/Dev-jffJP19G/lib/python3.9/site-packages/ncclient/manager.py", line 139, in connect_ssh
    session.connect(*args, **kwds)
  File "/home/admin/.local/share/virtualenvs/Dev-jffJP19G/lib/python3.9/site-packages/ncclient/transport/ssh.py", line 288, in connect
    raise SSHError("Could not open socket to %s:%s" % (host, port))
ncclient.transport.errors.SSHError: Could not open socket to 192.168.1.101:830

2024-06-26 10:25:06,058 - nornir.core.task -    ERROR -      start() - Host 'leaf2': task 'netconf_get_config' failed with traceback:
Traceback (most recent call last):
  File "/home/admin/.local/share/virtualenvs/Dev-jffJP19G/lib/python3.9/site-packages/nornir/core/task.py", line 99, in start
    r = self.task(self, **self.params)
  File "/home/admin/Dev/arista_vxlan_project/python_scripts/vlan_oper.py", line 11, in netconf_get_config
    with manager.connect(
  File "/home/admin/.local/share/virtualenvs/Dev-jffJP19G/lib/python3.9/site-packages/ncclient/manager.py", line 187, in connect
    return connect_ssh(*args, **kwds)
  File "/home/admin/.local/share/virtualenvs/Dev-jffJP19G/lib/python3.9/site-packages/ncclient/manager.py", line 139, in connect_ssh
    session.connect(*args, **kwds)
  File "/home/admin/.local/share/virtualenvs/Dev-jffJP19G/lib/python3.9/site-packages/ncclient/transport/ssh.py", line 288, in connect
    raise SSHError("Could not open socket to %s:%s" % (host, port))
ncclient.transport.errors.SSHError: Could not open socket to 192.168.1.103:830

2024-06-26 10:25:06,060 - nornir.core.task -    ERROR -      start() - Host 'leaf3': task 'netconf_get_config' failed with traceback:
Traceback (most recent call last):
  File "/home/admin/.local/share/virtualenvs/Dev-jffJP19G/lib/python3.9/site-packages/nornir/core/task.py", line 99, in start
    r = self.task(self, **self.params)
  File "/home/admin/Dev/arista_vxlan_project/python_scripts/vlan_oper.py", line 11, in netconf_get_config
    with manager.connect(
  File "/home/admin/.local/share/virtualenvs/Dev-jffJP19G/lib/python3.9/site-packages/ncclient/manager.py", line 187, in connect
    return connect_ssh(*args, **kwds)
  File "/home/admin/.local/share/virtualenvs/Dev-jffJP19G/lib/python3.9/site-packages/ncclient/manager.py", line 139, in connect_ssh
    session.connect(*args, **kwds)
  File "/home/admin/.local/share/virtualenvs/Dev-jffJP19G/lib/python3.9/site-packages/ncclient/transport/ssh.py", line 288, in connect
    raise SSHError("Could not open socket to %s:%s" % (host, port))
ncclient.transport.errors.SSHError: Could not open socket to 192.168.1.103:830

2024-06-26 10:25:06,061 - nornir.core.task -    ERROR -      start() - Host 'leaf1': task 'netconf_get_config' failed with traceback:
Traceback (most recent call last):
  File "/home/admin/.local/share/virtualenvs/Dev-jffJP19G/lib/python3.9/site-packages/nornir/core/task.py", line 99, in start
    r = self.task(self, **self.params)
  File "/home/admin/Dev/arista_vxlan_project/python_scripts/vlan_oper.py", line 11, in netconf_get_config
    with manager.connect(
  File "/home/admin/.local/share/virtualenvs/Dev-jffJP19G/lib/python3.9/site-packages/ncclient/manager.py", line 187, in connect
    return connect_ssh(*args, **kwds)
  File "/home/admin/.local/share/virtualenvs/Dev-jffJP19G/lib/python3.9/site-packages/ncclient/manager.py", line 139, in connect_ssh
    session.connect(*args, **kwds)
  File "/home/admin/.local/share/virtualenvs/Dev-jffJP19G/lib/python3.9/site-packages/ncclient/transport/ssh.py", line 288, in connect
    raise SSHError("Could not open socket to %s:%s" % (host, port))
ncclient.transport.errors.SSHError: Could not open socket to 192.168.1.102:830

2024-06-26 10:25:06,062 - nornir.core.task -    ERROR -      start() - Host 'leaf4': task 'netconf_get_config' failed with traceback:
Traceback (most recent call last):
  File "/home/admin/.local/share/virtualenvs/Dev-jffJP19G/lib/python3.9/site-packages/nornir/core/task.py", line 99, in start
    r = self.task(self, **self.params)
  File "/home/admin/Dev/arista_vxlan_project/python_scripts/vlan_oper.py", line 11, in netconf_get_config
    with manager.connect(
  File "/home/admin/.local/share/virtualenvs/Dev-jffJP19G/lib/python3.9/site-packages/ncclient/manager.py", line 187, in connect
    return connect_ssh(*args, **kwds)
  File "/home/admin/.local/share/virtualenvs/Dev-jffJP19G/lib/python3.9/site-packages/ncclient/manager.py", line 139, in connect_ssh
    session.connect(*args, **kwds)
  File "/home/admin/.local/share/virtualenvs/Dev-jffJP19G/lib/python3.9/site-packages/ncclient/transport/ssh.py", line 288, in connect
    raise SSHError("Could not open socket to %s:%s" % (host, port))
ncclient.transport.errors.SSHError: Could not open socket to 192.168.1.104:830

2024-06-26 10:27:32,442 -  nornir.core -     INFO -        run() - Running task 'netconf_get_config' with args {} on 6 hosts
2024-06-26 10:27:32,453 - nornir.core.task -    ERROR -      start() - Host 'spine2': task 'netconf_get_config' failed with traceback:
Traceback (most recent call last):
  File "/home/admin/.local/share/virtualenvs/Dev-jffJP19G/lib/python3.9/site-packages/nornir/core/task.py", line 99, in start
    r = self.task(self, **self.params)
  File "/home/admin/Dev/arista_vxlan_project/python_scripts/vlan_oper.py", line 11, in netconf_get_config
    with manager.connect(
  File "/home/admin/.local/share/virtualenvs/Dev-jffJP19G/lib/python3.9/site-packages/ncclient/manager.py", line 187, in connect
    return connect_ssh(*args, **kwds)
  File "/home/admin/.local/share/virtualenvs/Dev-jffJP19G/lib/python3.9/site-packages/ncclient/manager.py", line 139, in connect_ssh
    session.connect(*args, **kwds)
  File "/home/admin/.local/share/virtualenvs/Dev-jffJP19G/lib/python3.9/site-packages/ncclient/transport/ssh.py", line 288, in connect
    raise SSHError("Could not open socket to %s:%s" % (host, port))
ncclient.transport.errors.SSHError: Could not open socket to 192.168.1.101:830

2024-06-26 10:27:32,455 - nornir.core.task -    ERROR -      start() - Host 'leaf1': task 'netconf_get_config' failed with traceback:
Traceback (most recent call last):
  File "/home/admin/.local/share/virtualenvs/Dev-jffJP19G/lib/python3.9/site-packages/nornir/core/task.py", line 99, in start
    r = self.task(self, **self.params)
  File "/home/admin/Dev/arista_vxlan_project/python_scripts/vlan_oper.py", line 11, in netconf_get_config
    with manager.connect(
  File "/home/admin/.local/share/virtualenvs/Dev-jffJP19G/lib/python3.9/site-packages/ncclient/manager.py", line 187, in connect
    return connect_ssh(*args, **kwds)
  File "/home/admin/.local/share/virtualenvs/Dev-jffJP19G/lib/python3.9/site-packages/ncclient/manager.py", line 139, in connect_ssh
    session.connect(*args, **kwds)
  File "/home/admin/.local/share/virtualenvs/Dev-jffJP19G/lib/python3.9/site-packages/ncclient/transport/ssh.py", line 288, in connect
    raise SSHError("Could not open socket to %s:%s" % (host, port))
ncclient.transport.errors.SSHError: Could not open socket to 192.168.1.102:830

2024-06-26 10:27:32,455 - nornir.core.task -    ERROR -      start() - Host 'spine1': task 'netconf_get_config' failed with traceback:
Traceback (most recent call last):
  File "/home/admin/.local/share/virtualenvs/Dev-jffJP19G/lib/python3.9/site-packages/nornir/core/task.py", line 99, in start
    r = self.task(self, **self.params)
  File "/home/admin/Dev/arista_vxlan_project/python_scripts/vlan_oper.py", line 11, in netconf_get_config
    with manager.connect(
  File "/home/admin/.local/share/virtualenvs/Dev-jffJP19G/lib/python3.9/site-packages/ncclient/manager.py", line 187, in connect
    return connect_ssh(*args, **kwds)
  File "/home/admin/.local/share/virtualenvs/Dev-jffJP19G/lib/python3.9/site-packages/ncclient/manager.py", line 139, in connect_ssh
    session.connect(*args, **kwds)
  File "/home/admin/.local/share/virtualenvs/Dev-jffJP19G/lib/python3.9/site-packages/ncclient/transport/ssh.py", line 288, in connect
    raise SSHError("Could not open socket to %s:%s" % (host, port))
ncclient.transport.errors.SSHError: Could not open socket to 192.168.1.100:830

2024-06-26 10:27:32,458 - nornir.core.task -    ERROR -      start() - Host 'leaf3': task 'netconf_get_config' failed with traceback:
Traceback (most recent call last):
  File "/home/admin/.local/share/virtualenvs/Dev-jffJP19G/lib/python3.9/site-packages/nornir/core/task.py", line 99, in start
    r = self.task(self, **self.params)
  File "/home/admin/Dev/arista_vxlan_project/python_scripts/vlan_oper.py", line 11, in netconf_get_config
    with manager.connect(
  File "/home/admin/.local/share/virtualenvs/Dev-jffJP19G/lib/python3.9/site-packages/ncclient/manager.py", line 187, in connect
    return connect_ssh(*args, **kwds)
  File "/home/admin/.local/share/virtualenvs/Dev-jffJP19G/lib/python3.9/site-packages/ncclient/manager.py", line 139, in connect_ssh
    session.connect(*args, **kwds)
  File "/home/admin/.local/share/virtualenvs/Dev-jffJP19G/lib/python3.9/site-packages/ncclient/transport/ssh.py", line 288, in connect
    raise SSHError("Could not open socket to %s:%s" % (host, port))
ncclient.transport.errors.SSHError: Could not open socket to 192.168.1.103:830

2024-06-26 10:27:32,458 - nornir.core.task -    ERROR -      start() - Host 'leaf2': task 'netconf_get_config' failed with traceback:
Traceback (most recent call last):
  File "/home/admin/.local/share/virtualenvs/Dev-jffJP19G/lib/python3.9/site-packages/nornir/core/task.py", line 99, in start
    r = self.task(self, **self.params)
  File "/home/admin/Dev/arista_vxlan_project/python_scripts/vlan_oper.py", line 11, in netconf_get_config
    with manager.connect(
  File "/home/admin/.local/share/virtualenvs/Dev-jffJP19G/lib/python3.9/site-packages/ncclient/manager.py", line 187, in connect
    return connect_ssh(*args, **kwds)
  File "/home/admin/.local/share/virtualenvs/Dev-jffJP19G/lib/python3.9/site-packages/ncclient/manager.py", line 139, in connect_ssh
    session.connect(*args, **kwds)
  File "/home/admin/.local/share/virtualenvs/Dev-jffJP19G/lib/python3.9/site-packages/ncclient/transport/ssh.py", line 288, in connect
    raise SSHError("Could not open socket to %s:%s" % (host, port))
ncclient.transport.errors.SSHError: Could not open socket to 192.168.1.103:830

2024-06-26 10:27:32,459 - nornir.core.task -    ERROR -      start() - Host 'leaf4': task 'netconf_get_config' failed with traceback:
Traceback (most recent call last):
  File "/home/admin/.local/share/virtualenvs/Dev-jffJP19G/lib/python3.9/site-packages/nornir/core/task.py", line 99, in start
    r = self.task(self, **self.params)
  File "/home/admin/Dev/arista_vxlan_project/python_scripts/vlan_oper.py", line 11, in netconf_get_config
    with manager.connect(
  File "/home/admin/.local/share/virtualenvs/Dev-jffJP19G/lib/python3.9/site-packages/ncclient/manager.py", line 187, in connect
    return connect_ssh(*args, **kwds)
  File "/home/admin/.local/share/virtualenvs/Dev-jffJP19G/lib/python3.9/site-packages/ncclient/manager.py", line 139, in connect_ssh
    session.connect(*args, **kwds)
  File "/home/admin/.local/share/virtualenvs/Dev-jffJP19G/lib/python3.9/site-packages/ncclient/transport/ssh.py", line 288, in connect
    raise SSHError("Could not open socket to %s:%s" % (host, port))
ncclient.transport.errors.SSHError: Could not open socket to 192.168.1.104:830

2024-06-26 10:31:47,822 -  nornir.core -     INFO -        run() - Running task 'netconf_get_config' with args {} on 6 hosts
2024-06-26 10:31:47,833 - nornir.core.task -    ERROR -      start() - Host 'spine1': task 'netconf_get_config' failed with traceback:
Traceback (most recent call last):
  File "/home/admin/.local/share/virtualenvs/Dev-jffJP19G/lib/python3.9/site-packages/nornir/core/task.py", line 99, in start
    r = self.task(self, **self.params)
  File "/home/admin/Dev/arista_vxlan_project/python_scripts/vlan_oper.py", line 11, in netconf_get_config
    with manager.connect(
  File "/home/admin/.local/share/virtualenvs/Dev-jffJP19G/lib/python3.9/site-packages/ncclient/manager.py", line 187, in connect
    return connect_ssh(*args, **kwds)
  File "/home/admin/.local/share/virtualenvs/Dev-jffJP19G/lib/python3.9/site-packages/ncclient/manager.py", line 139, in connect_ssh
    session.connect(*args, **kwds)
  File "/home/admin/.local/share/virtualenvs/Dev-jffJP19G/lib/python3.9/site-packages/ncclient/transport/ssh.py", line 288, in connect
    raise SSHError("Could not open socket to %s:%s" % (host, port))
ncclient.transport.errors.SSHError: Could not open socket to 192.168.1.100:830

2024-06-26 10:31:47,835 - nornir.core.task -    ERROR -      start() - Host 'spine2': task 'netconf_get_config' failed with traceback:
Traceback (most recent call last):
  File "/home/admin/.local/share/virtualenvs/Dev-jffJP19G/lib/python3.9/site-packages/nornir/core/task.py", line 99, in start
    r = self.task(self, **self.params)
  File "/home/admin/Dev/arista_vxlan_project/python_scripts/vlan_oper.py", line 11, in netconf_get_config
    with manager.connect(
  File "/home/admin/.local/share/virtualenvs/Dev-jffJP19G/lib/python3.9/site-packages/ncclient/manager.py", line 187, in connect
    return connect_ssh(*args, **kwds)
  File "/home/admin/.local/share/virtualenvs/Dev-jffJP19G/lib/python3.9/site-packages/ncclient/manager.py", line 139, in connect_ssh
    session.connect(*args, **kwds)
  File "/home/admin/.local/share/virtualenvs/Dev-jffJP19G/lib/python3.9/site-packages/ncclient/transport/ssh.py", line 288, in connect
    raise SSHError("Could not open socket to %s:%s" % (host, port))
ncclient.transport.errors.SSHError: Could not open socket to 192.168.1.101:830

2024-06-26 10:31:47,838 - nornir.core.task -    ERROR -      start() - Host 'leaf2': task 'netconf_get_config' failed with traceback:
Traceback (most recent call last):
  File "/home/admin/.local/share/virtualenvs/Dev-jffJP19G/lib/python3.9/site-packages/nornir/core/task.py", line 99, in start
    r = self.task(self, **self.params)
  File "/home/admin/Dev/arista_vxlan_project/python_scripts/vlan_oper.py", line 11, in netconf_get_config
    with manager.connect(
  File "/home/admin/.local/share/virtualenvs/Dev-jffJP19G/lib/python3.9/site-packages/ncclient/manager.py", line 187, in connect
    return connect_ssh(*args, **kwds)
  File "/home/admin/.local/share/virtualenvs/Dev-jffJP19G/lib/python3.9/site-packages/ncclient/manager.py", line 139, in connect_ssh
    session.connect(*args, **kwds)
  File "/home/admin/.local/share/virtualenvs/Dev-jffJP19G/lib/python3.9/site-packages/ncclient/transport/ssh.py", line 288, in connect
    raise SSHError("Could not open socket to %s:%s" % (host, port))
ncclient.transport.errors.SSHError: Could not open socket to 192.168.1.103:830

2024-06-26 10:31:47,841 - nornir.core.task -    ERROR -      start() - Host 'leaf3': task 'netconf_get_config' failed with traceback:
Traceback (most recent call last):
  File "/home/admin/.local/share/virtualenvs/Dev-jffJP19G/lib/python3.9/site-packages/nornir/core/task.py", line 99, in start
    r = self.task(self, **self.params)
  File "/home/admin/Dev/arista_vxlan_project/python_scripts/vlan_oper.py", line 11, in netconf_get_config
    with manager.connect(
  File "/home/admin/.local/share/virtualenvs/Dev-jffJP19G/lib/python3.9/site-packages/ncclient/manager.py", line 187, in connect
    return connect_ssh(*args, **kwds)
  File "/home/admin/.local/share/virtualenvs/Dev-jffJP19G/lib/python3.9/site-packages/ncclient/manager.py", line 139, in connect_ssh
    session.connect(*args, **kwds)
  File "/home/admin/.local/share/virtualenvs/Dev-jffJP19G/lib/python3.9/site-packages/ncclient/transport/ssh.py", line 288, in connect
    raise SSHError("Could not open socket to %s:%s" % (host, port))
ncclient.transport.errors.SSHError: Could not open socket to 192.168.1.103:830

2024-06-26 10:31:47,846 - nornir.core.task -    ERROR -      start() - Host 'leaf4': task 'netconf_get_config' failed with traceback:
Traceback (most recent call last):
  File "/home/admin/.local/share/virtualenvs/Dev-jffJP19G/lib/python3.9/site-packages/nornir/core/task.py", line 99, in start
    r = self.task(self, **self.params)
  File "/home/admin/Dev/arista_vxlan_project/python_scripts/vlan_oper.py", line 11, in netconf_get_config
    with manager.connect(
  File "/home/admin/.local/share/virtualenvs/Dev-jffJP19G/lib/python3.9/site-packages/ncclient/manager.py", line 187, in connect
    return connect_ssh(*args, **kwds)
  File "/home/admin/.local/share/virtualenvs/Dev-jffJP19G/lib/python3.9/site-packages/ncclient/manager.py", line 139, in connect_ssh
    session.connect(*args, **kwds)
  File "/home/admin/.local/share/virtualenvs/Dev-jffJP19G/lib/python3.9/site-packages/ncclient/transport/ssh.py", line 288, in connect
    raise SSHError("Could not open socket to %s:%s" % (host, port))
ncclient.transport.errors.SSHError: Could not open socket to 192.168.1.104:830

2024-06-26 10:31:47,847 - nornir.core.task -    ERROR -      start() - Host 'leaf1': task 'netconf_get_config' failed with traceback:
Traceback (most recent call last):
  File "/home/admin/.local/share/virtualenvs/Dev-jffJP19G/lib/python3.9/site-packages/nornir/core/task.py", line 99, in start
    r = self.task(self, **self.params)
  File "/home/admin/Dev/arista_vxlan_project/python_scripts/vlan_oper.py", line 11, in netconf_get_config
    with manager.connect(
  File "/home/admin/.local/share/virtualenvs/Dev-jffJP19G/lib/python3.9/site-packages/ncclient/manager.py", line 187, in connect
    return connect_ssh(*args, **kwds)
  File "/home/admin/.local/share/virtualenvs/Dev-jffJP19G/lib/python3.9/site-packages/ncclient/manager.py", line 139, in connect_ssh
    session.connect(*args, **kwds)
  File "/home/admin/.local/share/virtualenvs/Dev-jffJP19G/lib/python3.9/site-packages/ncclient/transport/ssh.py", line 288, in connect
    raise SSHError("Could not open socket to %s:%s" % (host, port))
ncclient.transport.errors.SSHError: Could not open socket to 192.168.1.102:830

2024-06-26 10:33:07,562 -  nornir.core -     INFO -        run() - Running task 'netconf_get_config' with args {} on 6 hosts
2024-06-26 10:33:07,572 - nornir.core.task -    ERROR -      start() - Host 'spine1': task 'netconf_get_config' failed with traceback:
Traceback (most recent call last):
  File "/home/admin/.local/share/virtualenvs/Dev-jffJP19G/lib/python3.9/site-packages/nornir/core/task.py", line 99, in start
    r = self.task(self, **self.params)
  File "/home/admin/Dev/arista_vxlan_project/python_scripts/vlan_oper.py", line 11, in netconf_get_config
    with manager.connect(
  File "/home/admin/.local/share/virtualenvs/Dev-jffJP19G/lib/python3.9/site-packages/ncclient/manager.py", line 187, in connect
    return connect_ssh(*args, **kwds)
  File "/home/admin/.local/share/virtualenvs/Dev-jffJP19G/lib/python3.9/site-packages/ncclient/manager.py", line 139, in connect_ssh
    session.connect(*args, **kwds)
  File "/home/admin/.local/share/virtualenvs/Dev-jffJP19G/lib/python3.9/site-packages/ncclient/transport/ssh.py", line 288, in connect
    raise SSHError("Could not open socket to %s:%s" % (host, port))
ncclient.transport.errors.SSHError: Could not open socket to 192.168.1.100:830

2024-06-26 10:33:07,574 - nornir.core.task -    ERROR -      start() - Host 'spine2': task 'netconf_get_config' failed with traceback:
Traceback (most recent call last):
  File "/home/admin/.local/share/virtualenvs/Dev-jffJP19G/lib/python3.9/site-packages/nornir/core/task.py", line 99, in start
    r = self.task(self, **self.params)
  File "/home/admin/Dev/arista_vxlan_project/python_scripts/vlan_oper.py", line 11, in netconf_get_config
    with manager.connect(
  File "/home/admin/.local/share/virtualenvs/Dev-jffJP19G/lib/python3.9/site-packages/ncclient/manager.py", line 187, in connect
    return connect_ssh(*args, **kwds)
  File "/home/admin/.local/share/virtualenvs/Dev-jffJP19G/lib/python3.9/site-packages/ncclient/manager.py", line 139, in connect_ssh
    session.connect(*args, **kwds)
  File "/home/admin/.local/share/virtualenvs/Dev-jffJP19G/lib/python3.9/site-packages/ncclient/transport/ssh.py", line 288, in connect
    raise SSHError("Could not open socket to %s:%s" % (host, port))
ncclient.transport.errors.SSHError: Could not open socket to 192.168.1.101:830

2024-06-26 10:33:07,574 - nornir.core.task -    ERROR -      start() - Host 'leaf1': task 'netconf_get_config' failed with traceback:
Traceback (most recent call last):
  File "/home/admin/.local/share/virtualenvs/Dev-jffJP19G/lib/python3.9/site-packages/nornir/core/task.py", line 99, in start
    r = self.task(self, **self.params)
  File "/home/admin/Dev/arista_vxlan_project/python_scripts/vlan_oper.py", line 11, in netconf_get_config
    with manager.connect(
  File "/home/admin/.local/share/virtualenvs/Dev-jffJP19G/lib/python3.9/site-packages/ncclient/manager.py", line 187, in connect
    return connect_ssh(*args, **kwds)
  File "/home/admin/.local/share/virtualenvs/Dev-jffJP19G/lib/python3.9/site-packages/ncclient/manager.py", line 139, in connect_ssh
    session.connect(*args, **kwds)
  File "/home/admin/.local/share/virtualenvs/Dev-jffJP19G/lib/python3.9/site-packages/ncclient/transport/ssh.py", line 288, in connect
    raise SSHError("Could not open socket to %s:%s" % (host, port))
ncclient.transport.errors.SSHError: Could not open socket to 192.168.1.102:830

2024-06-26 10:33:07,576 - nornir.core.task -    ERROR -      start() - Host 'leaf3': task 'netconf_get_config' failed with traceback:
Traceback (most recent call last):
  File "/home/admin/.local/share/virtualenvs/Dev-jffJP19G/lib/python3.9/site-packages/nornir/core/task.py", line 99, in start
    r = self.task(self, **self.params)
  File "/home/admin/Dev/arista_vxlan_project/python_scripts/vlan_oper.py", line 11, in netconf_get_config
    with manager.connect(
  File "/home/admin/.local/share/virtualenvs/Dev-jffJP19G/lib/python3.9/site-packages/ncclient/manager.py", line 187, in connect
    return connect_ssh(*args, **kwds)
  File "/home/admin/.local/share/virtualenvs/Dev-jffJP19G/lib/python3.9/site-packages/ncclient/manager.py", line 139, in connect_ssh
    session.connect(*args, **kwds)
  File "/home/admin/.local/share/virtualenvs/Dev-jffJP19G/lib/python3.9/site-packages/ncclient/transport/ssh.py", line 288, in connect
    raise SSHError("Could not open socket to %s:%s" % (host, port))
ncclient.transport.errors.SSHError: Could not open socket to 192.168.1.103:830

2024-06-26 10:33:07,577 - nornir.core.task -    ERROR -      start() - Host 'leaf2': task 'netconf_get_config' failed with traceback:
Traceback (most recent call last):
  File "/home/admin/.local/share/virtualenvs/Dev-jffJP19G/lib/python3.9/site-packages/nornir/core/task.py", line 99, in start
    r = self.task(self, **self.params)
  File "/home/admin/Dev/arista_vxlan_project/python_scripts/vlan_oper.py", line 11, in netconf_get_config
    with manager.connect(
  File "/home/admin/.local/share/virtualenvs/Dev-jffJP19G/lib/python3.9/site-packages/ncclient/manager.py", line 187, in connect
    return connect_ssh(*args, **kwds)
  File "/home/admin/.local/share/virtualenvs/Dev-jffJP19G/lib/python3.9/site-packages/ncclient/manager.py", line 139, in connect_ssh
    session.connect(*args, **kwds)
  File "/home/admin/.local/share/virtualenvs/Dev-jffJP19G/lib/python3.9/site-packages/ncclient/transport/ssh.py", line 288, in connect
    raise SSHError("Could not open socket to %s:%s" % (host, port))
ncclient.transport.errors.SSHError: Could not open socket to 192.168.1.103:830

2024-06-26 10:33:07,579 - nornir.core.task -    ERROR -      start() - Host 'leaf4': task 'netconf_get_config' failed with traceback:
Traceback (most recent call last):
  File "/home/admin/.local/share/virtualenvs/Dev-jffJP19G/lib/python3.9/site-packages/nornir/core/task.py", line 99, in start
    r = self.task(self, **self.params)
  File "/home/admin/Dev/arista_vxlan_project/python_scripts/vlan_oper.py", line 11, in netconf_get_config
    with manager.connect(
  File "/home/admin/.local/share/virtualenvs/Dev-jffJP19G/lib/python3.9/site-packages/ncclient/manager.py", line 187, in connect
    return connect_ssh(*args, **kwds)
  File "/home/admin/.local/share/virtualenvs/Dev-jffJP19G/lib/python3.9/site-packages/ncclient/manager.py", line 139, in connect_ssh
    session.connect(*args, **kwds)
  File "/home/admin/.local/share/virtualenvs/Dev-jffJP19G/lib/python3.9/site-packages/ncclient/transport/ssh.py", line 288, in connect
    raise SSHError("Could not open socket to %s:%s" % (host, port))
ncclient.transport.errors.SSHError: Could not open socket to 192.168.1.104:830

2024-06-26 10:52:06,092 -  nornir.core -     INFO -        run() - Running task 'netconf_get_config' with args {} on 6 hosts
2024-06-26 10:55:51,074 -  nornir.core -     INFO -        run() - Running task 'netconf_get_config' with args {} on 1 hosts
2024-06-26 10:57:15,937 -  nornir.core -     INFO -        run() - Running task 'netconf_get_config' with args {} on 1 hosts
2024-06-26 10:58:08,954 -  nornir.core -     INFO -        run() - Running task 'netconf_get_config' with args {} on 1 hosts
2024-06-26 11:47:21,299 -  nornir.core -     INFO -        run() - Running task 'netconf_get_config' with args {} on 1 hosts
2024-06-26 11:47:21,301 - nornir.core.task -    ERROR -      start() - Host 'leaf1': task 'Get running config from each host' failed with traceback:
Traceback (most recent call last):
  File "/home/admin/.local/share/virtualenvs/Dev-jffJP19G/lib/python3.9/site-packages/nornir/core/task.py", line 99, in start
    r = self.task(self, **self.params)
TypeError: netconf_get_config() got an unexpected keyword argument 'source'

2024-06-26 11:47:21,301 - nornir.core.task -    ERROR -      start() - Host 'leaf1': task 'netconf_get_config' failed with traceback:
Traceback (most recent call last):
  File "/home/admin/.local/share/virtualenvs/Dev-jffJP19G/lib/python3.9/site-packages/nornir/core/task.py", line 99, in start
    r = self.task(self, **self.params)
  File "/home/admin/Dev/arista_vxlan_project/python_scripts/get_running_cfg.py", line 12, in netconf_get_config
    response = task.run(
  File "/home/admin/.local/share/virtualenvs/Dev-jffJP19G/lib/python3.9/site-packages/nornir/core/task.py", line 174, in run
    raise NornirSubTaskError(task=run_task, result=r)
nornir.core.exceptions.NornirSubTaskError: Subtask: Get running config from each host (failed)


2024-06-26 11:49:04,439 -  nornir.core -     INFO -        run() - Running task 'netconf_get_config' with args {} on 1 hosts
2024-06-26 11:49:04,442 - nornir.core.task -    ERROR -      start() - Host 'leaf1': task 'Get running config from each host' failed with traceback:
Traceback (most recent call last):
  File "/home/admin/.local/share/virtualenvs/Dev-jffJP19G/lib/python3.9/site-packages/nornir/core/task.py", line 99, in start
    r = self.task(self, **self.params)
TypeError: netconf_get() got an unexpected keyword argument 'source'

2024-06-26 11:49:04,442 - nornir.core.task -    ERROR -      start() - Host 'leaf1': task 'netconf_get_config' failed with traceback:
Traceback (most recent call last):
  File "/home/admin/.local/share/virtualenvs/Dev-jffJP19G/lib/python3.9/site-packages/nornir/core/task.py", line 99, in start
    r = self.task(self, **self.params)
  File "/home/admin/Dev/arista_vxlan_project/python_scripts/get_running_cfg.py", line 12, in netconf_get_config
    response = task.run(
  File "/home/admin/.local/share/virtualenvs/Dev-jffJP19G/lib/python3.9/site-packages/nornir/core/task.py", line 174, in run
    raise NornirSubTaskError(task=run_task, result=r)
nornir.core.exceptions.NornirSubTaskError: Subtask: Get running config from each host (failed)


2024-06-26 11:49:30,388 -  nornir.core -     INFO -        run() - Running task 'netconf_get_config' with args {} on 1 hosts
2024-06-26 11:49:31,168 - nornir.core.task -    ERROR -      start() - Host 'leaf1': task 'Get running config from each host' failed with traceback:
Traceback (most recent call last):
  File "/home/admin/.local/share/virtualenvs/Dev-jffJP19G/lib/python3.9/site-packages/nornir/core/task.py", line 99, in start
    r = self.task(self, **self.params)
  File "/home/admin/.local/share/virtualenvs/Dev-jffJP19G/lib/python3.9/site-packages/nornir_scrapli/tasks/netconf/get.py", line 28, in netconf_get
    scrapli_response = scrapli_conn.get(filter_=filter_, filter_type=filter_type)
  File "/home/admin/.local/share/virtualenvs/Dev-jffJP19G/lib/python3.9/site-packages/scrapli_netconf/driver/sync_driver.py", line 144, in get
    response = self._pre_get(filter_=filter_, filter_type=filter_type)
  File "/home/admin/.local/share/virtualenvs/Dev-jffJP19G/lib/python3.9/site-packages/scrapli_netconf/driver/base_driver.py", line 607, in _pre_get
    xml_filter_elem = self._build_filter(filter_=filter_, filter_type=filter_type)
  File "/home/admin/.local/share/virtualenvs/Dev-jffJP19G/lib/python3.9/site-packages/scrapli_netconf/driver/base_driver.py", line 473, in _build_filter
    if tmp_xml_filter_element.getchildren()[0].tag == "filter":
IndexError: list index out of range

2024-06-26 11:49:31,170 - nornir.core.task -    ERROR -      start() - Host 'leaf1': task 'netconf_get_config' failed with traceback:
Traceback (most recent call last):
  File "/home/admin/.local/share/virtualenvs/Dev-jffJP19G/lib/python3.9/site-packages/nornir/core/task.py", line 99, in start
    r = self.task(self, **self.params)
  File "/home/admin/Dev/arista_vxlan_project/python_scripts/get_running_cfg.py", line 12, in netconf_get_config
    response = task.run(
  File "/home/admin/.local/share/virtualenvs/Dev-jffJP19G/lib/python3.9/site-packages/nornir/core/task.py", line 174, in run
    raise NornirSubTaskError(task=run_task, result=r)
nornir.core.exceptions.NornirSubTaskError: Subtask: Get running config from each host (failed)


2024-06-26 11:50:50,204 -  nornir.core -     INFO -        run() - Running task 'netconf_get_config' with args {} on 1 hosts
2024-06-26 11:50:50,206 - nornir.core.task -    ERROR -      start() - Host 'leaf1': task 'Get running config from each host' failed with traceback:
Traceback (most recent call last):
  File "/home/admin/.local/share/virtualenvs/Dev-jffJP19G/lib/python3.9/site-packages/nornir/core/task.py", line 99, in start
    r = self.task(self, **self.params)
TypeError: netconf_get() got an unexpected keyword argument 'source'

2024-06-26 11:50:50,206 - nornir.core.task -    ERROR -      start() - Host 'leaf1': task 'netconf_get_config' failed with traceback:
Traceback (most recent call last):
  File "/home/admin/.local/share/virtualenvs/Dev-jffJP19G/lib/python3.9/site-packages/nornir/core/task.py", line 99, in start
    r = self.task(self, **self.params)
  File "/home/admin/Dev/arista_vxlan_project/python_scripts/get_running_cfg.py", line 12, in netconf_get_config
    response = task.run(
  File "/home/admin/.local/share/virtualenvs/Dev-jffJP19G/lib/python3.9/site-packages/nornir/core/task.py", line 174, in run
    raise NornirSubTaskError(task=run_task, result=r)
nornir.core.exceptions.NornirSubTaskError: Subtask: Get running config from each host (failed)


2024-06-26 11:51:01,788 -  nornir.core -     INFO -        run() - Running task 'netconf_get_config' with args {} on 1 hosts
2024-06-26 11:51:01,790 - nornir.core.task -    ERROR -      start() - Host 'leaf1': task 'Get running config from each host' failed with traceback:
Traceback (most recent call last):
  File "/home/admin/.local/share/virtualenvs/Dev-jffJP19G/lib/python3.9/site-packages/nornir/core/task.py", line 99, in start
    r = self.task(self, **self.params)
TypeError: netconf_get() missing 1 required positional argument: 'filter_'

2024-06-26 11:51:01,791 - nornir.core.task -    ERROR -      start() - Host 'leaf1': task 'netconf_get_config' failed with traceback:
Traceback (most recent call last):
  File "/home/admin/.local/share/virtualenvs/Dev-jffJP19G/lib/python3.9/site-packages/nornir/core/task.py", line 99, in start
    r = self.task(self, **self.params)
  File "/home/admin/Dev/arista_vxlan_project/python_scripts/get_running_cfg.py", line 12, in netconf_get_config
    response = task.run(
  File "/home/admin/.local/share/virtualenvs/Dev-jffJP19G/lib/python3.9/site-packages/nornir/core/task.py", line 174, in run
    raise NornirSubTaskError(task=run_task, result=r)
nornir.core.exceptions.NornirSubTaskError: Subtask: Get running config from each host (failed)


2024-06-26 11:53:00,356 -  nornir.core -     INFO -        run() - Running task 'backup_cfg' with args {} on 1 hosts
2024-06-26 11:53:01,539 - nornir.core.task -    ERROR -      start() - Host 'leaf1': task 'backup_cfg' failed with traceback:
Traceback (most recent call last):
  File "/home/admin/.local/share/virtualenvs/Dev-jffJP19G/lib/python3.9/site-packages/nornir/core/task.py", line 99, in start
    r = self.task(self, **self.params)
  File "/home/admin/Dev/arista_vxlan_project/python_scripts/get_running_cfg.py", line 31, in backup_cfg
    with open (f"./snapshots/configs/{task.host}.cfg", "w", encoding="utf-8") as file:
FileNotFoundError: [Errno 2] No such file or directory: './snapshots/configs/leaf1.cfg'

2024-06-26 12:00:51,395 -  nornir.core -     INFO -        run() - Running task 'netconf_get_config' with args {} on 1 hosts
2024-06-26 12:12:02,597 -  nornir.core -     INFO -        run() - Running task 'netconf_get_config' with args {} on 6 hosts
2024-06-26 12:23:06,370 -  nornir.core -     INFO -        run() - Running task 'netconf_get_config' with args {} on 1 hosts
2024-06-26 12:39:47,001 -  nornir.core -     INFO -        run() - Running task 'netconf_get_config' with args {'filter': None} on 1 hosts
2024-06-26 12:43:51,972 -  nornir.core -     INFO -        run() - Running task 'netconf_get_config' with args {'filter': '<interfaces xmlns="http://openconfig.net/yang/interfaces"/>'} on 1 hosts
2024-06-26 12:59:29,217 -  nornir.core -     INFO -        run() - Running task 'netconf_get_config' with args {'filter': '<interfaces xmlns="http://openconfig.net/yang/interfaces"/>'} on 1 hosts
2024-06-26 12:59:36,776 -  nornir.core -     INFO -        run() - Running task 'netconf_get_config' with args {'filter': '<interfaces xmlns="http://openconfig.net/yang/interfaces"/>'} on 1 hosts
2024-06-26 13:01:51,694 -  nornir.core -     INFO -        run() - Running task 'netconf_get_config' with args {'filter': '<interfaces xmlns="http://openconfig.net/yang/interfaces"/>'} on 1 hosts
2024-06-26 13:03:33,074 -  nornir.core -     INFO -        run() - Running task 'netconf_get_config' with args {'filter': '<interfaces xmlns="http://openconfig.net/yang/interfaces"/>'} on 1 hosts
2024-06-26 13:03:55,758 -  nornir.core -     INFO -        run() - Running task 'netconf_get_config' with args {'filter': '<interfaces xmlns="http://openconfig.net/yang/interfaces"/>'} on 1 hosts
2024-06-26 13:04:15,311 -  nornir.core -     INFO -        run() - Running task 'netconf_get_config' with args {'filter': '<interfaces xmlns="http://openconfig.net/yang/interfaces"/>'} on 1 hosts
2024-06-26 18:18:13,238 -  nornir.core -     INFO -        run() - Running task 'netconf_get_config' with args {'filter': '<interfaces xmlns="http://openconfig.net/yang/interfaces"/>'} on 1 hosts
2024-06-26 18:27:30,669 -  nornir.core -     INFO -        run() - Running task 'netconf_get_config' with args {'filter': '<interfaces xmlns="http://openconfig.net/yang/interfaces"/>'} on 1 hosts
2024-06-26 18:27:30,672 - nornir.core.task -    ERROR -      start() - Host 'leaf1': task 'netconf_get_config' failed with traceback:
Traceback (most recent call last):
  File "/home/admin/.local/share/virtualenvs/Dev-jffJP19G/lib/python3.9/site-packages/nornir/core/task.py", line 99, in start
    r = self.task(self, **self.params)
TypeError: netconf_get_config() got an unexpected keyword argument 'filter'

2024-06-26 18:27:38,930 -  nornir.core -     INFO -        run() - Running task 'netconf_get_config' with args {'filter': None} on 1 hosts
2024-06-26 18:27:38,932 - nornir.core.task -    ERROR -      start() - Host 'leaf1': task 'netconf_get_config' failed with traceback:
Traceback (most recent call last):
  File "/home/admin/.local/share/virtualenvs/Dev-jffJP19G/lib/python3.9/site-packages/nornir/core/task.py", line 99, in start
    r = self.task(self, **self.params)
TypeError: netconf_get_config() got an unexpected keyword argument 'filter'

2024-06-26 18:32:36,803 -  nornir.core -     INFO -        run() - Running task 'netconf_get_config' with args {'filter': None} on 1 hosts
2024-06-26 18:32:36,825 - nornir.core.task -    ERROR -      start() - Host 'leaf1': task 'netconf_get_config' failed with traceback:
Traceback (most recent call last):
  File "/home/admin/.local/share/virtualenvs/Dev-jffJP19G/lib/python3.9/site-packages/nornir/core/task.py", line 99, in start
    r = self.task(self, **self.params)
TypeError: netconf_get_config() got an unexpected keyword argument 'filter'

2024-06-26 18:36:41,952 -  nornir.core -     INFO -        run() - Running task 'netconf_get_config' with args {} on 1 hosts
2024-06-26 18:37:32,469 -  nornir.core -     INFO -        run() - Running task 'netconf_get_config' with args {} on 1 hosts
2024-06-26 18:37:44,508 -  nornir.core -     INFO -        run() - Running task 'netconf_get_config' with args {} on 1 hosts
2024-06-26 18:54:52,565 -  nornir.core -     INFO -        run() - Running task 'netconf_get_config' with args {} on 1 hosts
2024-06-26 18:55:46,640 -  nornir.core -     INFO -        run() - Running task 'netconf_get_config' with args {} on 1 hosts
2024-06-26 18:56:02,979 -  nornir.core -     INFO -        run() - Running task 'netconf_get_config' with args {} on 1 hosts
2024-06-26 19:05:03,440 -  nornir.core -     INFO -        run() - Running task 'netconf_get_config' with args {} on 1 hosts
2024-06-26 19:08:35,108 -  nornir.core -     INFO -        run() - Running task 'netconf_get_config' with args {} on 1 hosts
2024-06-26 19:08:51,233 -  nornir.core -     INFO -        run() - Running task 'netconf_get_config' with args {} on 1 hosts
2024-06-26 19:10:22,187 -  nornir.core -     INFO -        run() - Running task 'netconf_get_config' with args {} on 1 hosts
2024-06-26 19:10:32,377 -  nornir.core -     INFO -        run() - Running task 'netconf_get_config' with args {} on 1 hosts
2024-06-26 19:10:42,876 -  nornir.core -     INFO -        run() - Running task 'netconf_get_config' with args {} on 1 hosts
2024-06-26 20:30:26,509 -  nornir.core -     INFO -        run() - Running task 'netconf_get_config' with args {} on 1 hosts
2024-06-26 20:31:08,655 -  nornir.core -     INFO -        run() - Running task 'netconf_get_config' with args {} on 1 hosts
2024-06-26 20:34:04,110 -  nornir.core -     INFO -        run() - Running task 'netconf_get_config' with args {} on 1 hosts
2024-06-26 20:35:20,183 -  nornir.core -     INFO -        run() - Running task 'netconf_get_config' with args {} on 1 hosts
2024-06-26 20:35:33,121 -  nornir.core -     INFO -        run() - Running task 'netconf_get_config' with args {} on 1 hosts
2024-06-26 20:35:41,536 -  nornir.core -     INFO -        run() - Running task 'netconf_get_config' with args {} on 1 hosts
2024-06-26 20:39:12,942 -  nornir.core -     INFO -        run() - Running task 'netconf_get_config' with args {} on 1 hosts
2024-06-26 20:40:45,791 -  nornir.core -     INFO -        run() - Running task 'netconf_get_config' with args {} on 1 hosts
2024-06-26 20:41:57,581 -  nornir.core -     INFO -        run() - Running task 'netconf_get_config' with args {} on 1 hosts
2024-06-26 20:58:55,375 -  nornir.core -     INFO -        run() - Running task 'netconf_get_config' with args {} on 1 hosts
2024-06-26 21:03:08,413 -  nornir.core -     INFO -        run() - Running task 'netconf_get_config' with args {} on 1 hosts
2024-06-26 21:03:24,556 -  nornir.core -     INFO -        run() - Running task 'netconf_get_config' with args {} on 1 hosts
2024-06-26 21:04:01,677 -  nornir.core -     INFO -        run() - Running task 'netconf_get_config' with args {} on 1 hosts
2024-06-26 21:08:56,361 -  nornir.core -     INFO -        run() - Running task 'netconf_get_config' with args {} on 1 hosts
2024-06-26 21:10:32,962 -  nornir.core -     INFO -        run() - Running task 'netconf_get_config' with args {} on 1 hosts
2024-06-26 21:15:37,778 -  nornir.core -     INFO -        run() - Running task 'netconf_get_config' with args {} on 1 hosts
2024-06-26 23:50:20,072 -  nornir.core -     INFO -        run() - Running task 'netconf_get_config' with args {'filter': '\n    <interfaces xmlns="http://openconfig.net/yang/interfaces">\n        <interface>\n            <name>Ethernet3</name>\n        </interface>\n    </interfaces>\n    '} on 1 hosts
2024-06-26 23:50:20,074 - nornir.core.task -    ERROR -      start() - Host 'spine1': task 'netconf_get_config' failed with traceback:
Traceback (most recent call last):
  File "/home/admin/.local/share/virtualenvs/Dev-jffJP19G/lib/python3.9/site-packages/nornir/core/task.py", line 99, in start
    r = self.task(self, **self.params)
TypeError: netconf_get_config() got an unexpected keyword argument 'filter'

2024-06-26 23:51:30,562 -  nornir.core -     INFO -        run() - Running task 'netconf_get_config' with args {} on 1 hosts
2024-06-26 23:51:59,393 -  nornir.core -     INFO -        run() - Running task 'netconf_get_config' with args {} on 1 hosts
2024-06-26 23:55:39,426 -  nornir.core -     INFO -        run() - Running task 'netconf_get_config' with args {} on 1 hosts
2024-06-26 23:56:11,789 -  nornir.core -     INFO -        run() - Running task 'netconf_get_config' with args {} on 1 hosts
2024-06-26 23:56:21,227 -  nornir.core -     INFO -        run() - Running task 'netconf_get_config' with args {} on 1 hosts
2024-06-26 23:58:16,905 -  nornir.core -     INFO -        run() - Running task 'netconf_get_config' with args {} on 1 hosts
2024-06-26 23:59:28,745 -  nornir.core -     INFO -        run() - Running task 'netconf_get_config' with args {} on 1 hosts
2024-06-27 00:00:22,903 -  nornir.core -     INFO -        run() - Running task 'netconf_get_config' with args {} on 1 hosts
2024-06-27 00:04:32,365 -  nornir.core -     INFO -        run() - Running task 'netconf_get_config' with args {} on 1 hosts
2024-06-27 00:07:51,794 -  nornir.core -     INFO -        run() - Running task 'netconf_get_config' with args {} on 1 hosts
2024-06-27 00:09:29,841 -  nornir.core -     INFO -        run() - Running task 'netconf_get_config' with args {} on 1 hosts
2024-06-27 00:09:49,174 -  nornir.core -     INFO -        run() - Running task 'netconf_get_config' with args {} on 1 hosts
